Workbook

Sheet Dashboard
A1: LLE Experiments Dashboard
A4: DES Systems
A5: Aroma | B5: Solvents | C5: Tie Lines | D5: Status
A7: 2-phenylethanol | B7: 9 DES | C7: 45 | D7: TODO: Ratio
A11: Data Sources:
A12: • Componentes: Densities (col P), MW (col M), Purity (col I)

Sheet Componentes
A1: IDENTIFICADOR | G1: INVENTARIO | M1: PROPIEDADES | S1: SEGURIDAD | V1: METADATA
A2: ID | B2: Chemical Name | C2: Common Name(s) | D2: CAS Number | E2: Formula | F2: Canonical SMILES | G2: Location | H2: Supplier | I2: Grade/Purity | J2: Lot Number | K2: Quantity | L2: Unit | M2: MW | N2: Tb | O2: Tm | P2: ρ (25°C) | Q2: η (25°C) | R2: Pᵛᵃᵖ (25°C) | S2: Flash Point | T2: Hazard Class | U2: Storage | V2: Date Received | W2: Status | X2: Notes | AA2: comp_id | AB2: MW | AC2: purity
A3: Internal component code | B3: IUPAC or standard name | C3: Alternative names | D3: CAS registry number | E3: Molecular formula | F3: For modeling/databases | G3: Lab position (e.g., 3.1) | H3: Vendor name | I3: (Según batch) | J3: Batch identifier | K3: Amount available | L3: mL, g, kg, etc. | M3: g/mol | N3: °C (1 atm) | O3: °C | P3: g/cm³ | Q3: mPa·s | R3: kPa | S3: °C | T3: GHS classification | U3: Requirements | V3: YYYY-MM-DD | W3: Active/Depleted | X3: Additional info | AA3: beta | AB3: 192.3 | AC3: 0.978
A4: beta | B4: b-ionone (trans) | C4: - | D4: 14901-07-6 | E4: C13H20O | F4: CC1=C(C(CCC1)(C)C)/C=C/C(=O)C | G4: REFRIGERADOR | H4: Sigma-Aldrich | I4: 97.8% (GC) | J4: SHBL2869 | K4: 1 | L4: L | M4: 192.3 | N4: 266 | O4: - | P4: 0.94498 | R4: - | S4: - | T4: - | U4: - | V4: - | W4: Active | AA4: 2pe | AB4: 122.16 | AC4: 1
A5: 2pe | B5: 2-phenylethanol | C5: - | D5: 60-12-8 | E5: C8H10O | F5: OCCc1ccccc1 | G5: 3.x | H5: Sigma-Aldrich | I5: > 99.9% (GC) | J5: SDBB2371 | K5: 1 | L5: L | M5: 122.16 | N5: 219 | O5: - | P5: 1.01985 | R5: - | S5: - | T5: - | U5: - | V5: - | W5: Active | AA5: gamma | AB5: 170.25 | AC5: 0.987
A6: gamma | B6: g-decalactone | C6: - | D6: 706-14-9 | E6: C10H18O2 | F6: CCCCCCC1CCC(=O)O1 | G6: 3.x | H6: Sigma-Aldrich | I6: 98.7% (GC) | J6: SHBR4960 | K6: 1 | L6: L | M6: 170.25 | N6: 285 | O6: - | P6: 0.95292 | R6: - | S6: - | T6: - | U6: - | V6: - | W6: Active | AA6: 2m3b2oh | AB6: 86.13 | AC6: 0.996
A7: 2m3b2oh | B7: 2-methyl-3-buten-2-ol | C7: 2M3B2OH | D7: 115-18-4 | E7: C5H10O | F7: CC(C)(C=C)O | G7: REFRIGERADOR | H7: Aldrich | I7: 99.6% (GC) | J7: STBH5331 | K7: 1 | L7: L | M7: 86.13 | N7: 99 | O7: - | P7: 0.82388 | R7: - | S7: - | T7: - | U7: - | V7: - | W7: Active | AA7: 2m2boh | AB7: 88.15 | AC7: 1
A8: 2m2boh | B8: 2-methyl-2-butanol | C8: tert-amyl alcohol | D8: 75-85-4 | E8: C5H12O | F8: CCC(C)(C)O | G8: 3.2 | H8: Sigma-Aldrich | I8: >99.9% (GC) | J8: SDBB4598 | K8: 1 | L8: L | M8: 88.15 | N8: 102 | O8: - | P8: 0.80899 | R8: - | S8: - | T8: - | U8: - | V8: - | W8: Active | AA8: hexoh | AB8: 102.17 | AC8: 0.998
A9: hexoh | B9: 1-hexanol | C9: - | D9: 111-27-3 | E9: C6H18O | F9: CCCCCCO | G9: 1.3. | H9: Sigma-Aldrich | I9: 99.8% (GC) | J9: SHBC9189V | K9: 700 | L9: mL | M9: 102.17 | N9: 156 | O9: - | P9: 0.81883 | R9: - | S9: - | T9: - | U9: - | V9: - | W9: Active | AA9: octoh | AB9: 130.23 | AC9: 0.997
A10: octoh | B10: 1-octanol | C10: - | D10: 111-87-5 | E10: C8H18O | F10: CCCCCCCCO | G10: 1.2 | H10: Sigma-Aldrich | I10: 99.7% (GC) | J10: SDBB1117 | K10: 200? | L10: mL | M10: 130.23 | N10: 195 | O10: - | P10: 0.82518 | R10: - | S10: - | T10: - | U10: - | V10: - | W10: Active | AA10: mibk | AB10: 100.16 | AC10: 0.998
A11: mibk | B11: methyl isobutyl ketone | C11: MIBK | D11: 108-10-1 | E11: C6H12O | F11: CC(C)CC(=O)C | G11: 2.4 | H11: Merck Millipor | I11: 99.8% (GC) | J11: K51239346927 | K11: 300? | L11: mL | M11: 100.16 | N11: 115 | O11: - | P11: 0.80143 | R11: - | S11: - | T11: - | U11: - | V11: - | W11: Active | AA11: 2octanone | AB11: 128.21 | AC11: 0.988
A12: 2octanone | B12: 2-octanone | C12: Hexyl methyl ketone | D12: 111-13-7 | E12: C8H16O | F12: CCCCCCC(=O)C | G12: 3.2 | H12: Sigma-Aldrich | I12: 98.8% (GC) | J12: SHBQ4121 | K12: 200? | L12: mL | M12: 128.21 | N12: 173 | O12: - | P12: 0.81906 | R12: - | S12: - | T12: - | U12: - | V12: - | W12: Active | AA12: thymol | AB12: 150.22 | AC12: 0.999
A13: thymol | B13: Thymol | C13: - | D13: 89-83-8 | E13: C10H14O | F13: Cc1ccc(C(C)C)c(O)c1 | G13: 1.2 | H13: Sigma-Aldrich | I13: >99.9% (GC) | J13: SHBQ5769 | K13: 800 | L13: g | M13: 150.22 | N13: 233 | O13: - | P13: 0.96 | R13: - | S13: - | T13: - | U13: - | V13: - | W13: Active | AA13: carvone | AB13: 150.22 | AC13: 0.992
A14: carvone | B14: L-Carvone | C14: (-)-Carvone | D14: 6485-40-1 | E14: C10H14O | F14: C=C(C)[C@@H]1CC=C(C)C(=O)C1 | G14: 1.2 | H14: Sigma-Aldrich | I14: 99.2% (GC) | J14: SHBQ8402 | K14: 1 | L14: kg | M14: 150.22 | N14: 226 | O14: - | P14: 0.96 | R14: - | S14: - | T14: - | U14: - | V14: - | W14: Active | AA14: camphor | AB14: 152.24 | AC14: 0.969
A15: camphor | B15: DL-Camphor | C15: - | D15: 76-22-2 | E15: C10H16O | F15: CC1(C)C2CCC1(C)C(=O)C2 | G15: 3.2 | H15: Sigma-Aldrich | I15: 96.9% (GC) | J15: SDBB0718 | K15: 250 | L15: g | M15: 152.24 | N15: 210 | O15: - | P15: 0.99 | R15: - | S15: - | T15: - | U15: - | V15: - | W15: Active | AA15: geraniol | AB15: 154.25 | AC15: 0.989
A16: geraniol | B16: Geraniol | C16: - | D16: 106-24-1 | E16: C10H18O | F16: CC(C)=CCC/C(C)=C/CO | G16: 2.3 | H16: Sigma-Aldrich | I16: 98.9% (GC) | J16: SHBP7700 | K16: 700 | L16: g | M16: 154.25 | N16: 229 | O16: - | P16: 0.889 | R16: - | S16: - | T16: - | U16: - | V16: - | W16: Active | AA16: carvacrol | AB16: 150.22 | AC16: 0.997
A17: carvacrol | B17: Carvacrol | C17: - | D17: 499-75-2 | E17: C10H14O | F17: Cc1ccc(C(C)C)cc1O | G17: 2.1 | H17: Sigma-Aldrich | I17: 99.7% (GC) | J17: SHBQ9085 | K17: 400? | L17: mL | M17: 150.22 | N17: 239 | O17: - | P17: 0.977 | R17: - | S17: - | T17: - | U17: - | V17: - | W17: Active | AA17: eugenol | AB17: 164.2 | AC17: 0.992
A18: eugenol | B18: Eugenol | C18: - | D18: 97-53-0 | E18: C10H12O2 | F18: C=CCc1ccc(O)c(OC)c1 | G18: 1.3 | H18: Sigma-Aldrich | I18: 99.2% (GC) | J18: SHBM4053 | K18: 500? | L18: mL | M18: 164.2 | N18: 215 | O18: - | P18: 1.06 | R18: - | S18: - | T18: - | U18: - | V18: - | W18: Active
A19: h2o | B19: Water | C19: - | D19: - | E19: - | G19: - | H19: - | I19: HPLC | J19: - | K19: - | L19: - | M19: 18.02 | N19: 100 | O19: - | R19: - | S19: - | T19: - | U19: - | V19: - | W19: Active
B21: Aroma (soluto)
B22: Solventes
B23: DESs
B24: Agua (diluyente)

Sheet datos_des
B2: LLE con agua | C2: ThyCar | D2: ThyGer | E2: ThyCarvon | F2: ThyEug | G2: CamCar | H2: CamGer | I2: CamCarvac | J2: CamEug
B3: b-ionona | L3: HBA | M3: HBD
B4: 2-phenylethanol | K4: 1 | L4: Thymol | M4: Carvone | N4: 1
B5: g-decalactone | K5: 2 | L5: Camphor | M5: Geraniol | N5: 2
M6: Carvacrol | N6: 3
B7: VLE | C7: ThyCar | D7: ThyGer | E7: ThyCarvon | F7: ThyEug | G7: CamCar | H7: CamGer | I7: CamCarvac | J7: CamEug | M7: Eugenol | N7: 4
B8: b-ionona
B9: 2-phenylethanol
B10: g-decalactone
C12: Falta fleck
B14: PREPARACIÓN DES 10.00 g (1:1 molar)
B15: m_total: | C15: 10 | D15: g
B16: DES | C16: HBA | D16: MW_HBA | E16: Pureza_HBA | F16: m_HBA target (g) | G16: m_HBA exp (g) | H16: HBD | I16: MW_HBD | J16: Pureza_HBD | K16: m_HBD target (g) | L16: m_HBD exp (g) | M16: n_HBA/n_HBD
B17: ThyCar | C17: thymol | D17: =VLOOKUP(C17,Componentes!$AA$3:$AC$17,2,FALSE()) -> 150.22 | E17: =VLOOKUP(C17,Componentes!$AA$3:$AC$17,3,FALSE()) -> 0.999 | F17: =$C$15*D17/(D17+I17)/E17 -> 5.005005 | G17: 5.0064 | H17: carvone | I17: =VLOOKUP(H17,Componentes!$AA$3:$AC$17,2,FALSE()) -> 150.22 | J17: =VLOOKUP(H17,Componentes!$AA$3:$AC$17,3,FALSE()) -> 0.992 | K17: =$C$15*I17/(D17+I17)/J17 -> 5.0403226 | L17: 5.0469 | M17: =IF(AND(G17<>"",L17<>""),(G17*E17/D17)/(L17*J17/I17),"") -> 0.9989751
B18: ThyGer | C18: thymol | D18: =VLOOKUP(C18,Componentes!$AA$3:$AC$17,2,FALSE()) -> 150.22 | E18: =VLOOKUP(C18,Componentes!$AA$3:$AC$17,3,FALSE()) -> 0.999 | F18: =$C$15*D18/(D18+I18)/E18 -> 4.9387582 | G18: 4.95 | H18: geraniol | I18: =VLOOKUP(H18,Componentes!$AA$3:$AC$17,2,FALSE()) -> 154.25 | J18: =VLOOKUP(H18,Componentes!$AA$3:$AC$17,3,FALSE()) -> 0.989 | K18: =$C$15*I18/(D18+I18)/J18 -> 5.1225284 | L18: 5.1232 | M18: =IF(AND(G18<>"",L18<>""),(G18*E18/D18)/(L18*J18/I18),"") -> 1.0021449
B19: ThyCarvac | C19: thymol | D19: =VLOOKUP(C19,Componentes!$AA$3:$AC$17,2,FALSE()) -> 150.22 | E19: =VLOOKUP(C19,Componentes!$AA$3:$AC$17,3,FALSE()) -> 0.999 | F19: =$C$15*D19/(D19+I19)/E19 -> 5.005005 | G19: 5.0063 | H19: carvacrol | I19: =VLOOKUP(H19,Componentes!$AA$3:$AC$17,2,FALSE()) -> 150.22 | J19: =VLOOKUP(H19,Componentes!$AA$3:$AC$17,3,FALSE()) -> 0.997 | K19: =$C$15*I19/(D19+I19)/J19 -> 5.0150451 | L19: 5.0156 | M19: =IF(AND(G19<>"",L19<>""),(G19*E19/D19)/(L19*J19/I19),"") -> 1.0001481
B20: ThyEug | C20: thymol | D20: =VLOOKUP(C20,Componentes!$AA$3:$AC$17,2,FALSE()) -> 150.22 | E20: =VLOOKUP(C20,Componentes!$AA$3:$AC$17,3,FALSE()) -> 0.999 | F20: =$C$15*D20/(D20+I20)/E20 -> 4.7824684 | H20: eugenol | I20: =VLOOKUP(H20,Componentes!$AA$3:$AC$17,2,FALSE()) -> 164.2 | J20: =VLOOKUP(H20,Componentes!$AA$3:$AC$17,3,FALSE()) -> 0.992 | K20: =$C$15*I20/(D20+I20)/J20 -> 5.2644295 | M20: =IF(AND(G20<>"",L20<>""),(G20*E20/D20)/(L20*J20/I20),"")
B21: ThyCam | C21: thymol | D21: =VLOOKUP(C21,Componentes!$AA$3:$AC$17,2,FALSE()) -> 150.22 | E21: =VLOOKUP(C21,Componentes!$AA$3:$AC$17,3,FALSE()) -> 0.999 | F21: =$C$15*D21/(D21+I21)/E21 -> 4.9715787 | G21: =1.6711+1.6663+1.6953 -> 5.0327 | H21: camphor | I21: =VLOOKUP(H21,Componentes!$AA$3:$AC$17,2,FALSE()) -> 152.24 | J21: =VLOOKUP(H21,Componentes!$AA$3:$AC$17,3,FALSE()) -> 0.969 | K21: =$C$15*I21/(D21+I21)/J21 -> 5.1944199 | L21: =1.7344+1.7354+1.7709 -> 5.2407 | M21: =IF(AND(G21<>"",L21<>""),(G21*E21/D21)/(L21*J21/I21),"") -> 1.0033547
B22: CamCar | C22: camphor | D22: =VLOOKUP(C22,Componentes!$AA$3:$AC$17,2,FALSE()) -> 152.24 | E22: =VLOOKUP(C22,Componentes!$AA$3:$AC$17,3,FALSE()) -> 0.969 | F22: =$C$15*D22/(D22+I22)/E22 -> 5.1944199 | G22: 5.2014 | H22: carvone | I22: =VLOOKUP(H22,Componentes!$AA$3:$AC$17,2,FALSE()) -> 150.22 | J22: =VLOOKUP(H22,Componentes!$AA$3:$AC$17,3,FALSE()) -> 0.992 | K22: =$C$15*I22/(D22+I22)/J22 -> 5.0066604 | L22: 5.0074 | M22: =IF(AND(G22<>"",L22<>""),(G22*E22/D22)/(L22*J22/I22),"") -> 1.0011959
B23: CamGer | C23: camphor | D23: =VLOOKUP(C23,Componentes!$AA$3:$AC$17,2,FALSE()) -> 152.24 | E23: =VLOOKUP(C23,Componentes!$AA$3:$AC$17,3,FALSE()) -> 0.969 | F23: =$C$15*D23/(D23+I23)/E23 -> 5.1261191 | G23: 5.1236 | H23: geraniol | I23: =VLOOKUP(H23,Componentes!$AA$3:$AC$17,2,FALSE()) -> 154.25 | J23: =VLOOKUP(H23,Componentes!$AA$3:$AC$17,3,FALSE()) -> 0.989 | K23: =$C$15*I23/(D23+I23)/J23 -> 5.0887671 | L23: 5.084 | M23: =IF(AND(G23<>"",L23<>""),(G23*E23/D23)/(L23*J23/I23),"") -> 1.0004458 | N23: NO SE FORMA
B24: CamCarvac | C24: camphor | D24: =VLOOKUP(C24,Componentes!$AA$3:$AC$17,2,FALSE()) -> 152.24 | E24: =VLOOKUP(C24,Componentes!$AA$3:$AC$17,3,FALSE()) -> 0.969 | F24: =$C$15*D24/(D24+I24)/E24 -> 5.1944199 | H24: carvacrol | I24: =VLOOKUP(H24,Componentes!$AA$3:$AC$17,2,FALSE()) -> 150.22 | J24: =VLOOKUP(H24,Componentes!$AA$3:$AC$17,3,FALSE()) -> 0.997 | K24: =$C$15*I24/(D24+I24)/J24 -> 4.9815518 | M24: =IF(AND(G24<>"",L24<>""),(G24*E24/D24)/(L24*J24/I24),"")
B25: CamEug | C25: camphor | D25: =VLOOKUP(C25,Componentes!$AA$3:$AC$17,2,FALSE()) -> 152.24 | E25: =VLOOKUP(C25,Componentes!$AA$3:$AC$17,3,FALSE()) -> 0.969 | F25: =$C$15*D25/(D25+I25)/E25 -> 4.9649356 | H25: eugenol | I25: =VLOOKUP(H25,Componentes!$AA$3:$AC$17,2,FALSE()) -> 164.2 | J25: =VLOOKUP(H25,Componentes!$AA$3:$AC$17,3,FALSE()) -> 0.992 | K25: =$C$15*I25/(D25+I25)/J25 -> 5.230824 | M25: =IF(AND(G25<>"",L25<>""),(G25*E25/D25)/(L25*J25/I25),"")
B27: Amarillo: ingreso experimental | E27: Verde: calculado desde Componentes

Sheet Sheet1
A1: PREPARACIÓN DES 5.00 g (1:1 molar)
A3: DES | B3: HBA | C3: MW_HBA | D3: Pureza_HBA | E3: m_HBA target (g) | F3: m_HBA exp (g) | G3: HBD | H3: MW_HBD | I3: Pureza_HBD | J3: m_HBD target (g) | K3: m_HBD exp (g) | L3: n_HBA/n_HBD | N3: DES | O3: HBA | P3: MW_HBA | Q3: Pureza_HBA | R3: m_HBA target (g) | S3: m_HBA exp (g) | T3: HBD | U3: MW_HBD | V3: Pureza_HBD | W3: m_HBD target (g) | X3: m_HBD exp (g) | Y3: n_HBA/n_HBD
A4: ThyCar | B4: thymol | C4: =VLOOKUP(B4,Componentes!$AA$3:$AC$17,2,FALSE()) -> 150.22 | D4: =VLOOKUP(B4,Componentes!$AA$3:$AC$17,3,FALSE()) -> 0.999 | E4: =$C$15*C4/(C4+H4)/D4 -> 2.5025025 | G4: carvone | H4: =VLOOKUP(G4,Componentes!$AA$3:$AC$17,2,FALSE()) -> 150.22 | I4: =VLOOKUP(G4,Componentes!$AA$3:$AC$17,3,FALSE()) -> 0.992 | J4: =$C$15*H4/(C4+H4)/I4 -> 2.5201613 | L4: =IF(AND(F4<>"",K4<>""),(F4*D4/C4)/(K4*I4/H4),"") | N4: ThyEug | O4: thymol | P4: =VLOOKUP(O4,Componentes!$AA$3:$AC$17,2,FALSE()) -> 150.22 | Q4: =VLOOKUP(O4,Componentes!$AA$3:$AC$17,3,FALSE()) -> 0.999 | R4: =$C$15*P4/(P4+U4)/Q4 -> 2.3912342 | T4: eugenol | U4: =VLOOKUP(T4,Componentes!$AA$3:$AC$17,2,FALSE()) -> 164.2 | V4: =VLOOKUP(T4,Componentes!$AA$3:$AC$17,3,FALSE()) -> 0.992 | W4: =$C$15*U4/(P4+U4)/V4 -> 2.6322148 | Y4: =IF(AND(S4<>"",X4<>""),(S4*Q4/P4)/(X4*V4/U4),"")
A5: ThyGer | B5: thymol | C5: =VLOOKUP(B5,Componentes!$AA$3:$AC$17,2,FALSE()) -> 150.22 | D5: =VLOOKUP(B5,Componentes!$AA$3:$AC$17,3,FALSE()) -> 0.999 | E5: =$C$15*C5/(C5+H5)/D5 -> 2.4693791 | G5: geraniol | H5: =VLOOKUP(G5,Componentes!$AA$3:$AC$17,2,FALSE()) -> 154.25 | I5: =VLOOKUP(G5,Componentes!$AA$3:$AC$17,3,FALSE()) -> 0.989 | J5: =$C$15*H5/(C5+H5)/I5 -> 2.5612642 | L5: =IF(AND(F5<>"",K5<>""),(F5*D5/C5)/(K5*I5/H5),"") | N5: CamCarvac | O5: camphor | P5: =VLOOKUP(O5,Componentes!$AA$3:$AC$17,2,FALSE()) -> 152.24 | Q5: =VLOOKUP(O5,Componentes!$AA$3:$AC$17,3,FALSE()) -> 0.969 | R5: =$C$15*P5/(P5+U5)/Q5 -> 2.5972099 | T5: carvacrol | U5: =VLOOKUP(T5,Componentes!$AA$3:$AC$17,2,FALSE()) -> 150.22 | V5: =VLOOKUP(T5,Componentes!$AA$3:$AC$17,3,FALSE()) -> 0.997 | W5: =$C$15*U5/(P5+U5)/V5 -> 2.4907759 | Y5: =IF(AND(S5<>"",X5<>""),(S5*Q5/P5)/(X5*V5/U5),"")
A6: ThyCarvac | B6: thymol | C6: =VLOOKUP(B6,Componentes!$AA$3:$AC$17,2,FALSE()) -> 150.22 | D6: =VLOOKUP(B6,Componentes!$AA$3:$AC$17,3,FALSE()) -> 0.999 | E6: =$C$15*C6/(C6+H6)/D6 -> 2.5025025 | G6: carvacrol | H6: =VLOOKUP(G6,Componentes!$AA$3:$AC$17,2,FALSE()) -> 150.22 | I6: =VLOOKUP(G6,Componentes!$AA$3:$AC$17,3,FALSE()) -> 0.997 | J6: =$C$15*H6/(C6+H6)/I6 -> 2.5075226 | L6: =IF(AND(F6<>"",K6<>""),(F6*D6/C6)/(K6*I6/H6),"") | N6: CamEug | O6: camphor | P6: =VLOOKUP(O6,Componentes!$AA$3:$AC$17,2,FALSE()) -> 152.24 | Q6: =VLOOKUP(O6,Componentes!$AA$3:$AC$17,3,FALSE()) -> 0.969 | R6: =$C$15*P6/(P6+U6)/Q6 -> 2.4824678 | T6: eugenol | U6: =VLOOKUP(T6,Componentes!$AA$3:$AC$17,2,FALSE()) -> 164.2 | V6: =VLOOKUP(T6,Componentes!$AA$3:$AC$17,3,FALSE()) -> 0.992 | W6: =$C$15*U6/(P6+U6)/V6 -> 2.615412 | Y6: =IF(AND(S6<>"",X6<>""),(S6*Q6/P6)/(X6*V6/U6),"")
A7: ThyEug | B7: thymol | C7: =VLOOKUP(B7,Componentes!$AA$3:$AC$17,2,FALSE()) -> 150.22 | D7: =VLOOKUP(B7,Componentes!$AA$3:$AC$17,3,FALSE()) -> 0.999 | E7: =$C$15*C7/(C7+H7)/D7 -> 2.3912342 | G7: eugenol | H7: =VLOOKUP(G7,Componentes!$AA$3:$AC$17,2,FALSE()) -> 164.2 | I7: =VLOOKUP(G7,Componentes!$AA$3:$AC$17,3,FALSE()) -> 0.992 | J7: =$C$15*H7/(C7+H7)/I7 -> 2.6322148 | L7: =IF(AND(F7<>"",K7<>""),(F7*D7/C7)/(K7*I7/H7),"")
A8: ThyCam | B8: thymol | C8: =VLOOKUP(B8,Componentes!$AA$3:$AC$17,2,FALSE()) -> 150.22 | D8: =VLOOKUP(B8,Componentes!$AA$3:$AC$17,3,FALSE()) -> 0.999 | E8: =$C$15*C8/(C8+H8)/D8 -> 2.4857894 | G8: camphor | H8: =VLOOKUP(G8,Componentes!$AA$3:$AC$17,2,FALSE()) -> 152.24 | I8: =VLOOKUP(G8,Componentes!$AA$3:$AC$17,3,FALSE()) -> 0.969 | J8: =$C$15*H8/(C8+H8)/I8 -> 2.5972099 | L8: =IF(AND(F8<>"",K8<>""),(F8*D8/C8)/(K8*I8/H8),"")
A9: CamCar | B9: camphor | C9: =VLOOKUP(B9,Componentes!$AA$3:$AC$17,2,FALSE()) -> 152.24 | D9: =VLOOKUP(B9,Componentes!$AA$3:$AC$17,3,FALSE()) -> 0.969 | E9: =$C$15*C9/(C9+H9)/D9 -> 2.5972099 | G9: carvone | H9: =VLOOKUP(G9,Componentes!$AA$3:$AC$17,2,FALSE()) -> 150.22 | I9: =VLOOKUP(G9,Componentes!$AA$3:$AC$17,3,FALSE()) -> 0.992 | J9: =$C$15*H9/(C9+H9)/I9 -> 2.5033302 | L9: =IF(AND(F9<>"",K9<>""),(F9*D9/C9)/(K9*I9/H9),"")
A10: CamGer | B10: camphor | C10: =VLOOKUP(B10,Componentes!$AA$3:$AC$17,2,FALSE()) -> 152.24 | D10: =VLOOKUP(B10,Componentes!$AA$3:$AC$17,3,FALSE()) -> 0.969 | E10: =$C$15*C10/(C10+H10)/D10 -> 2.5630595 | G10: geraniol | H10: =VLOOKUP(G10,Componentes!$AA$3:$AC$17,2,FALSE()) -> 154.25 | I10: =VLOOKUP(G10,Componentes!$AA$3:$AC$17,3,FALSE()) -> 0.989 | J10: =$C$15*H10/(C10+H10)/I10 -> 2.5443835 | L10: =IF(AND(F10<>"",K10<>""),(F10*D10/C10)/(K10*I10/H10),"")
A11: CamCarvac | B11: camphor | C11: =VLOOKUP(B11,Componentes!$AA$3:$AC$17,2,FALSE()) -> 152.24 | D11: =VLOOKUP(B11,Componentes!$AA$3:$AC$17,3,FALSE()) -> 0.969 | E11: =$C$15*C11/(C11+H11)/D11 -> 2.5972099 | G11: carvacrol | H11: =VLOOKUP(G11,Componentes!$AA$3:$AC$17,2,FALSE()) -> 150.22 | I11: =VLOOKUP(G11,Componentes!$AA$3:$AC$17,3,FALSE()) -> 0.997 | J11: =$C$15*H11/(C11+H11)/I11 -> 2.4907759 | L11: =IF(AND(F11<>"",K11<>""),(F11*D11/C11)/(K11*I11/H11),"")
A12: CamEug | B12: camphor | C12: =VLOOKUP(B12,Componentes!$AA$3:$AC$17,2,FALSE()) -> 152.24 | D12: =VLOOKUP(B12,Componentes!$AA$3:$AC$17,3,FALSE()) -> 0.969 | E12: =$C$15*C12/(C12+H12)/D12 -> 2.4824678 | G12: eugenol | H12: =VLOOKUP(G12,Componentes!$AA$3:$AC$17,2,FALSE()) -> 164.2 | I12: =VLOOKUP(G12,Componentes!$AA$3:$AC$17,3,FALSE()) -> 0.992 | J12: =$C$15*H12/(C12+H12)/I12 -> 2.615412 | L12: =IF(AND(F12<>"",K12<>""),(F12*D12/C12)/(K12*I12/H12),"")
C15: 5

Sheet 2-phenylethanol_DES
A1: LLE Ternario: 2-phenylethanol + DES + Water
A2: Target mass (g): | B2: 100 | C2: ← change here to rescale all masses
A3: Yellow = paste z (mass fracs) from software | Green = auto-calculated
A5: # | B5: DES | C5: HBA | D5: HBD | E5: Ratio | F5: TL# | G5: z_aroma | H5: z_DES | I5: z_water | J5: Σz (check) | K5: m_aroma (g) | L5: m_DES (g) | M5: m_water (g) | N5: m_total (g)
A6: 1 | B6: ThyCar | C6: Thymol | D6: Carvone | E6: 1:1 | F6: 1 | G6: 0.02048 | H6: 0.47645 | I6: 0.50307 | J6: =IF(G6="","",G6+H6+I6) -> 1 | K6: =IF(G6="","",G6*$B$2) -> 2.048 | L6: =IF(H6="","",H6*$B$2) -> 47.645 | M6: =IF(I6="","",I6*$B$2) -> 50.307 | N6: =IF(K6="","",K6+L6+M6) -> 100
A7: 2 | E7: 1:1 | F7: 2 | G7: 0.47529 | H7: 0.02048 | I7: 0.50422 | J7: =IF(G7="","",G7+H7+I7) -> 0.99999 | K7: =IF(G7="","",G7*$B$2) -> 47.529 | L7: =IF(H7="","",H7*$B$2) -> 2.048 | M7: =IF(I7="","",I7*$B$2) -> 50.422 | N7: =IF(K7="","",K7+L7+M7) -> 99.999
A8: 3 | E8: 1:1 | F8: 3 | G8: 0.24503 | H8: 0.25452 | I8: 0.50045 | J8: =IF(G8="","",G8+H8+I8) -> 1 | K8: =IF(G8="","",G8*$B$2) -> 24.503 | L8: =IF(H8="","",H8*$B$2) -> 25.452 | M8: =IF(I8="","",I8*$B$2) -> 50.045 | N8: =IF(K8="","",K8+L8+M8) -> 100
A9: 4 | E9: 1:1 | F9: 4 | G9: 0.13276 | H9: 0.36622 | I9: 0.50102 | J9: =IF(G9="","",G9+H9+I9) -> 1 | K9: =IF(G9="","",G9*$B$2) -> 13.276 | L9: =IF(H9="","",H9*$B$2) -> 36.622 | M9: =IF(I9="","",I9*$B$2) -> 50.102 | N9: =IF(K9="","",K9+L9+M9) -> 100
A10: 5 | E10: 1:1 | F10: 5 | G10: 0.35944 | H10: 0.13914 | I10: 0.50142 | J10: =IF(G10="","",G10+H10+I10) -> 1 | K10: =IF(G10="","",G10*$B$2) -> 35.944 | L10: =IF(H10="","",H10*$B$2) -> 13.914 | M10: =IF(I10="","",I10*$B$2) -> 50.142 | N10: =IF(K10="","",K10+L10+M10) -> 100
A12: 6 | B12: ThyGer | C12: Thymol | D12: Geraniol | E12: 1:1 | F12: 1 | G12: 0.47452 | H12: 0.02001 | I12: 0.50547 | J12: =IF(G12="","",G12+H12+I12) -> 1 | K12: =IF(G12="","",G12*$B$2) -> 47.452 | L12: =IF(H12="","",H12*$B$2) -> 2.001 | M12: =IF(I12="","",I12*$B$2) -> 50.547 | N12: =IF(K12="","",K12+L12+M12) -> 100
A13: 7 | E13: 1:1 | F13: 2 | G13: 0.02072 | H13: 0.45539 | I13: 0.52389 | J13: =IF(G13="","",G13+H13+I13) -> 1 | K13: =IF(G13="","",G13*$B$2) -> 2.072 | L13: =IF(H13="","",H13*$B$2) -> 45.539 | M13: =IF(I13="","",I13*$B$2) -> 52.389 | N13: =IF(K13="","",K13+L13+M13) -> 100
A14: 8 | E14: 1:1 | F14: 3 | G14: 0.24795 | H14: 0.23883 | I14: 0.51322 | J14: =IF(G14="","",G14+H14+I14) -> 1 | K14: =IF(G14="","",G14*$B$2) -> 24.795 | L14: =IF(H14="","",H14*$B$2) -> 23.883 | M14: =IF(I14="","",I14*$B$2) -> 51.322 | N14: =IF(K14="","",K14+L14+M14) -> 100
A15: 9 | E15: 1:1 | F15: 4 | G15: 0.13477 | H15: 0.34704 | I15: 0.51819 | J15: =IF(G15="","",G15+H15+I15) -> 1 | K15: =IF(G15="","",G15*$B$2) -> 13.477 | L15: =IF(H15="","",H15*$B$2) -> 34.704 | M15: =IF(I15="","",I15*$B$2) -> 51.819 | N15: =IF(K15="","",K15+L15+M15) -> 100
A16: 10 | E16: 1:1 | F16: 5 | G16: 0.36056 | H16: 0.13046 | I16: 0.50898 | J16: =IF(G16="","",G16+H16+I16) -> 1 | K16: =IF(G16="","",G16*$B$2) -> 36.056 | L16: =IF(H16="","",H16*$B$2) -> 13.046 | M16: =IF(I16="","",I16*$B$2) -> 50.898 | N16: =IF(K16="","",K16+L16+M16) -> 100
A18: 11 | B18: ThyCarvac | C18: Thymol | D18: Carvacrol | E18: 1:1 | F18: 1 | G18: 0.47439 | H18: 0.02051 | I18: 0.5051 | J18: =IF(G18="","",G18+H18+I18) -> 1 | K18: =IF(G18="","",G18*$B$2) -> 47.439 | L18: =IF(H18="","",H18*$B$2) -> 2.051 | M18: =IF(I18="","",I18*$B$2) -> 50.51 | N18: =IF(K18="","",K18+L18+M18) -> 100
A19: 12 | E19: 1:1 | F19: 2 | G19: 0.02032 | H19: 0.46755 | I19: 0.51214 | J19: =IF(G19="","",G19+H19+I19) -> 1.00001 | K19: =IF(G19="","",G19*$B$2) -> 2.032 | L19: =IF(H19="","",H19*$B$2) -> 46.755 | M19: =IF(I19="","",I19*$B$2) -> 51.214 | N19: =IF(K19="","",K19+L19+M19) -> 100.001
A20: 13 | E20: 1:1 | F20: 3 | G20: 0.2465 | H20: 0.24556 | I20: 0.50794 | J20: =IF(G20="","",G20+H20+I20) -> 1 | K20: =IF(G20="","",G20*$B$2) -> 24.65 | L20: =IF(H20="","",H20*$B$2) -> 24.556 | M20: =IF(I20="","",I20*$B$2) -> 50.794 | N20: =IF(K20="","",K20+L20+M20) -> 100
A21: 14 | E21: 1:1 | F21: 4 | G21: 0.1329 | H21: 0.35721 | I21: 0.50989 | J21: =IF(G21="","",G21+H21+I21) -> 1 | K21: =IF(G21="","",G21*$B$2) -> 13.29 | L21: =IF(H21="","",H21*$B$2) -> 35.721 | M21: =IF(I21="","",I21*$B$2) -> 50.989 | N21: =IF(K21="","",K21+L21+M21) -> 100
A22: 15 | E22: 1:1 | F22: 5 | G22: 0.35977 | H22: 0.1339 | I22: 0.50634 | J22: =IF(G22="","",G22+H22+I22) -> 1.00001 | K22: =IF(G22="","",G22*$B$2) -> 35.977 | L22: =IF(H22="","",H22*$B$2) -> 13.39 | M22: =IF(I22="","",I22*$B$2) -> 50.634 | N22: =IF(K22="","",K22+L22+M22) -> 100.001
A24: 16 | B24: ThyEug | C24: Thymol | D24: Eugenol | E24: 1:1 | F24: 1 | G24: 0.47573 | H24: 0.02001 | I24: 0.50426 | J24: =IF(G24="","",G24+H24+I24) -> 1 | K24: =IF(G24="","",G24*$B$2) -> 47.573 | L24: =IF(H24="","",H24*$B$2) -> 2.001 | M24: =IF(I24="","",I24*$B$2) -> 50.426 | N24: =IF(K24="","",K24+L24+M24) -> 100
A25: 17 | E25: 1:1 | F25: 2 | G25: 0.02082 | H25: 0.47311 | I25: 0.50606 | J25: =IF(G25="","",G25+H25+I25) -> 0.99999 | K25: =IF(G25="","",G25*$B$2) -> 2.082 | L25: =IF(H25="","",H25*$B$2) -> 47.311 | M25: =IF(I25="","",I25*$B$2) -> 50.606 | N25: =IF(K25="","",K25+L25+M25) -> 99.999
A26: 18 | E26: 1:1 | F26: 3 | G26: 0.24474 | H26: 0.25403 | I26: 0.50124 | J26: =IF(G26="","",G26+H26+I26) -> 1.00001 | K26: =IF(G26="","",G26*$B$2) -> 24.474 | L26: =IF(H26="","",H26*$B$2) -> 25.403 | M26: =IF(I26="","",I26*$B$2) -> 50.124 | N26: =IF(K26="","",K26+L26+M26) -> 100.001
A27: 19 | E27: 1:1 | F27: 4 | G27: 0.35862 | H27: 0.13975 | I27: 0.50163 | J27: =IF(G27="","",G27+H27+I27) -> 1 | K27: =IF(G27="","",G27*$B$2) -> 35.862 | L27: =IF(H27="","",H27*$B$2) -> 13.975 | M27: =IF(I27="","",I27*$B$2) -> 50.163 | N27: =IF(K27="","",K27+L27+M27) -> 100
A28: 20 | E28: 1:1 | F28: 5 | G28: 0.13271 | H28: 0.36448 | I28: 0.50281 | J28: =IF(G28="","",G28+H28+I28) -> 1 | K28: =IF(G28="","",G28*$B$2) -> 13.271 | L28: =IF(H28="","",H28*$B$2) -> 36.448 | M28: =IF(I28="","",I28*$B$2) -> 50.281 | N28: =IF(K28="","",K28+L28+M28) -> 100
A30: 21 | B30: ThyCam | C30: Thymol | D30: Camphor | E30: 1:1 | F30: 1 | G30: 0.0203 | H30: 0.47651 | I30: 0.50319 | J30: =IF(G30="","",G30+H30+I30) -> 1 | K30: =IF(G30="","",G30*$B$2) -> 2.03 | L30: =IF(H30="","",H30*$B$2) -> 47.651 | M30: =IF(I30="","",I30*$B$2) -> 50.319 | N30: =IF(K30="","",K30+L30+M30) -> 100
A31: 22 | E31: 1:1 | F31: 2 | G31: 0.47512 | H31: 0.02061 | I31: 0.50426 | J31: =IF(G31="","",G31+H31+I31) -> 0.99999 | K31: =IF(G31="","",G31*$B$2) -> 47.512 | L31: =IF(H31="","",H31*$B$2) -> 2.061 | M31: =IF(I31="","",I31*$B$2) -> 50.426 | N31: =IF(K31="","",K31+L31+M31) -> 99.999
A32: 23 | E32: 1:1 | F32: 3 | G32: 0.24476 | H32: 0.25451 | I32: 0.50073 | J32: =IF(G32="","",G32+H32+I32) -> 1 | K32: =IF(G32="","",G32*$B$2) -> 24.476 | L32: =IF(H32="","",H32*$B$2) -> 25.451 | M32: =IF(I32="","",I32*$B$2) -> 50.073 | N32: =IF(K32="","",K32+L32+M32) -> 100
A33: 24 | E33: 1:1 | F33: 4 | G33: 0.13232 | H33: 0.36642 | I33: 0.50126 | J33: =IF(G33="","",G33+H33+I33) -> 1 | K33: =IF(G33="","",G33*$B$2) -> 13.232 | L33: =IF(H33="","",H33*$B$2) -> 36.642 | M33: =IF(I33="","",I33*$B$2) -> 50.126 | N33: =IF(K33="","",K33+L33+M33) -> 100
A34: 25 | E34: 1:1 | F34: 5 | G34: 0.35859 | H34: 0.13977 | I34: 0.50163 | J34: =IF(G34="","",G34+H34+I34) -> 0.99999 | K34: =IF(G34="","",G34*$B$2) -> 35.859 | L34: =IF(H34="","",H34*$B$2) -> 13.977 | M34: =IF(I34="","",I34*$B$2) -> 50.163 | N34: =IF(K34="","",K34+L34+M34) -> 99.999
A36: 26 | B36: CamCar | C36: Camphor | D36: Carvone | E36: 1:1 | F36: 1 | G36: 0.02055 | H36: 0.48113 | I36: 0.49832 | J36: =IF(G36="","",G36+H36+I36) -> 1 | K36: =IF(G36="","",G36*$B$2) -> 2.055 | L36: =IF(H36="","",H36*$B$2) -> 48.113 | M36: =IF(I36="","",I36*$B$2) -> 49.832 | N36: =IF(K36="","",K36+L36+M36) -> 100
A37: 27 | E37: 1:1 | F37: 2 | G37: 0.476 | H37: 0.02061 | I37: 0.50339 | J37: =IF(G37="","",G37+H37+I37) -> 1 | K37: =IF(G37="","",G37*$B$2) -> 47.6 | L37: =IF(H37="","",H37*$B$2) -> 2.061 | M37: =IF(I37="","",I37*$B$2) -> 50.339 | N37: =IF(K37="","",K37+L37+M37) -> 100
A38: 28 | E38: 1:1 | F38: 3 | G38: 0.24392 | H38: 0.26133 | I38: 0.49475 | J38: =IF(G38="","",G38+H38+I38) -> 1 | K38: =IF(G38="","",G38*$B$2) -> 24.392 | L38: =IF(H38="","",H38*$B$2) -> 26.133 | M38: =IF(I38="","",I38*$B$2) -> 49.475 | N38: =IF(K38="","",K38+L38+M38) -> 100
A39: 29 | E39: 1:1 | F39: 4 | G39: 0.35809 | H39: 0.14474 | I39: 0.49717 | J39: =IF(G39="","",G39+H39+I39) -> 1 | K39: =IF(G39="","",G39*$B$2) -> 35.809 | L39: =IF(H39="","",H39*$B$2) -> 14.474 | M39: =IF(I39="","",I39*$B$2) -> 49.717 | N39: =IF(K39="","",K39+L39+M39) -> 100
A40: 30 | E40: 1:1 | F40: 5 | G40: 0.13213 | H40: 0.37292 | I40: 0.49495 | J40: =IF(G40="","",G40+H40+I40) -> 1 | K40: =IF(G40="","",G40*$B$2) -> 13.213 | L40: =IF(H40="","",H40*$B$2) -> 37.292 | M40: =IF(I40="","",I40*$B$2) -> 49.495 | N40: =IF(K40="","",K40+L40+M40) -> 100
A42: 31 | B42: CamGer | C42: Camphor | D42: Geraniol | E42: 1:1 | F42: 1 | G42: 0.02003 | H42: 0.4642 | I42: 0.51577 | J42: =IF(G42="","",G42+H42+I42) -> 1 | K42: =IF(G42="","",G42*$B$2) -> 2.003 | L42: =IF(H42="","",H42*$B$2) -> 46.42 | M42: =IF(I42="","",I42*$B$2) -> 51.577 | N42: =IF(K42="","",K42+L42+M42) -> 100
A43: 32 | E43: 1:1 | F43: 2 | G43: 0.47522 | H43: 0.02013 | I43: 0.50465 | J43: =IF(G43="","",G43+H43+I43) -> 1 | K43: =IF(G43="","",G43*$B$2) -> 47.522 | L43: =IF(H43="","",H43*$B$2) -> 2.013 | M43: =IF(I43="","",I43*$B$2) -> 50.465 | N43: =IF(K43="","",K43+L43+M43) -> 100
A44: 33 | E44: 1:1 | F44: 3 | G44: 0.24608 | H44: 0.24734 | I44: 0.50658 | J44: =IF(G44="","",G44+H44+I44) -> 1 | K44: =IF(G44="","",G44*$B$2) -> 24.608 | L44: =IF(H44="","",H44*$B$2) -> 24.734 | M44: =IF(I44="","",I44*$B$2) -> 50.658 | N44: =IF(K44="","",K44+L44+M44) -> 100
A45: 34 | E45: 1:1 | F45: 4 | G45: 0.35967 | H45: 0.13575 | I45: 0.50458 | J45: =IF(G45="","",G45+H45+I45) -> 1 | K45: =IF(G45="","",G45*$B$2) -> 35.967 | L45: =IF(H45="","",H45*$B$2) -> 13.575 | M45: =IF(I45="","",I45*$B$2) -> 50.458 | N45: =IF(K45="","",K45+L45+M45) -> 100
A46: 35 | E46: 1:1 | F46: 5 | G46: 0.13286 | H46: 0.35682 | I46: 0.51032 | J46: =IF(G46="","",G46+H46+I46) -> 1 | K46: =IF(G46="","",G46*$B$2) -> 13.286 | L46: =IF(H46="","",H46*$B$2) -> 35.682 | M46: =IF(I46="","",I46*$B$2) -> 51.032 | N46: =IF(K46="","",K46+L46+M46) -> 100
A48: 36 | B48: CamCarvac | C48: Camphor | D48: Carvacrol | E48: 1:1 | F48: 1 | G48: 0.02035 | H48: 0.47845 | I48: 0.5012 | J48: =IF(G48="","",G48+H48+I48) -> 1 | K48: =IF(G48="","",G48*$B$2) -> 2.035 | L48: =IF(H48="","",H48*$B$2) -> 47.845 | M48: =IF(I48="","",I48*$B$2) -> 50.12 | N48: =IF(K48="","",K48+L48+M48) -> 100
...

Sheet Lab_DES
B1: 2-phenylethanol + DES + Water
A4: ρ_aroma (g/mL): | B4: =Componentes!P4 -> 0.94498 | C4: 2-phenylethanol
A5: ρ_water (g/mL): | B5: 0.997
B7: Guía | D7: Anotar | F7: Record on balance
A9: # | B9: DES | C9: HBA | D9: HBD | E9: TL# | F9: ρ_DES est (g/mL) | G9: V_agua est (mL) | H9: V_aroma est (mL) | I9: V_DES est (mL) | J9: W_tubo (g) | K9: W + agua (g) | L9: W + aroma (g) | M9: W + DES (g) | N9: m_water (g) | O9: m_aroma (g) | P9: m_DES (g) | Q9: m_total (g) | R9: w_water | S9: w_aroma | T9: w_DES | U9: Notas
A10: A1 | B10: ThyCar | C10: Thymol | D10: Carvone | E10: 1 | F10: =(Componentes!AB12/(Componentes!AB12+Componentes!AB13))*Componentes!P12+(Componentes!AB13/(Componentes!AB12+Componentes!AB13))*Componentes!P13 -> 0.88953 | G10: =IF('2-phenylethanol_DES'!I6="","",'2-phenylethanol_DES'!I6*7/$B$5) -> 3.5320863 | H10: =IF('2-phenylethanol_DES'!G6="","",'2-phenylethanol_DES'!G6*7/$B$4) -> 0.15170691 | I10: =IF('2-phenylethanol_DES'!H6="","",'2-phenylethanol_DES'!H6*7/F10) -> 3.7493395 | N10: =IF(OR(J10="",K10=""),"",K10-J10) | O10: =IF(OR(K10="",L10=""),"",L10-K10) | P10: =IF(OR(L10="",M10=""),"",M10-L10) | Q10: =IF(OR(J10="",M10=""),"",M10-J10) | R10: =IF(Q10="","",N10/Q10) | S10: =IF(Q10="","",O10/Q10) | T10: =IF(Q10="","",P10/Q10)
A11: A2 | E11: 2 | F11: =(Componentes!AB12/(Componentes!AB12+Componentes!AB13))*Componentes!P12+(Componentes!AB13/(Componentes!AB12+Componentes!AB13))*Componentes!P13 -> 0.88953 | G11: =IF('2-phenylethanol_DES'!I7="","",'2-phenylethanol_DES'!I7*7/$B$5) -> 3.5401605 | H11: =IF('2-phenylethanol_DES'!G7="","",'2-phenylethanol_DES'!G7*7/$B$4) -> 3.5207412 | I11: =IF('2-phenylethanol_DES'!H7="","",'2-phenylethanol_DES'!H7*7/F11) -> 0.16116376 | N11: =IF(OR(J11="",K11=""),"",K11-J11) | O11: =IF(OR(K11="",L11=""),"",L11-K11) | P11: =IF(OR(L11="",M11=""),"",M11-L11) | Q11: =IF(OR(J11="",M11=""),"",M11-J11) | R11: =IF(Q11="","",N11/Q11) | S11: =IF(Q11="","",O11/Q11) | T11: =IF(Q11="","",P11/Q11)
A12: A3 | E12: 3 | F12: =(Componentes!AB12/(Componentes!AB12+Componentes!AB13))*Componentes!P12+(Componentes!AB13/(Componentes!AB12+Componentes!AB13))*Componentes!P13 -> 0.88953 | G12: =IF('2-phenylethanol_DES'!I8="","",'2-phenylethanol_DES'!I8*7/$B$5) -> 3.5136911 | H12: =IF('2-phenylethanol_DES'!G8="","",'2-phenylethanol_DES'!G8*7/$B$4) -> 1.8150755 | I12: =IF('2-phenylethanol_DES'!H8="","",'2-phenylethanol_DES'!H8*7/F12) -> 2.0029004 | N12: =IF(OR(J12="",K12=""),"",K12-J12) | O12: =IF(OR(K12="",L12=""),"",L12-K12) | P12: =IF(OR(L12="",M12=""),"",M12-L12) | Q12: =IF(OR(J12="",M12=""),"",M12-J12) | R12: =IF(Q12="","",N12/Q12) | S12: =IF(Q12="","",O12/Q12) | T12: =IF(Q12="","",P12/Q12)
A13: A4 | E13: 4 | F13: =(Componentes!AB12/(Componentes!AB12+Componentes!AB13))*Componentes!P12+(Componentes!AB13/(Componentes!AB12+Componentes!AB13))*Componentes!P13 -> 0.88953 | G13: =IF('2-phenylethanol_DES'!I9="","",'2-phenylethanol_DES'!I9*7/$B$5) -> 3.5176931 | H13: =IF('2-phenylethanol_DES'!G9="","",'2-phenylethanol_DES'!G9*7/$B$4) -> 0.98342822 | I13: =IF('2-phenylethanol_DES'!H9="","",'2-phenylethanol_DES'!H9*7/F13) -> 2.8819039 | N13: =IF(OR(J13="",K13=""),"",K13-J13) | O13: =IF(OR(K13="",L13=""),"",L13-K13) | P13: =IF(OR(L13="",M13=""),"",M13-L13) | Q13: =IF(OR(J13="",M13=""),"",M13-J13) | R13: =IF(Q13="","",N13/Q13) | S13: =IF(Q13="","",O13/Q13) | T13: =IF(Q13="","",P13/Q13)
A14: A5 | E14: 5 | F14: =(Componentes!AB12/(Componentes!AB12+Componentes!AB13))*Componentes!P12+(Componentes!AB13/(Componentes!AB12+Componentes!AB13))*Componentes!P13 -> 0.88953 | G14: =IF('2-phenylethanol_DES'!I10="","",'2-phenylethanol_DES'!I10*7/$B$5) -> 3.5205015 | H14: =IF('2-phenylethanol_DES'!G10="","",'2-phenylethanol_DES'!G10*7/$B$4) -> 2.6625749 | I14: =IF('2-phenylethanol_DES'!H10="","",'2-phenylethanol_DES'!H10*7/F14) -> 1.0949378 | N14: =IF(OR(J14="",K14=""),"",K14-J14) | O14: =IF(OR(K14="",L14=""),"",L14-K14) | P14: =IF(OR(L14="",M14=""),"",M14-L14) | Q14: =IF(OR(J14="",M14=""),"",M14-J14) | R14: =IF(Q14="","",N14/Q14) | S14: =IF(Q14="","",O14/Q14) | T14: =IF(Q14="","",P14/Q14)
A16: B1 | B16: ThyGer | C16: Thymol | D16: Geraniol | E16: 1 | F16: =(Componentes!AB12/(Componentes!AB12+Componentes!AB15))*Componentes!P12+(Componentes!AB15/(Componentes!AB12+Componentes!AB15))*Componentes!P15 -> 0.90566129 | G16: =IF('2-phenylethanol_DES'!I12="","",'2-phenylethanol_DES'!I12*7/$B$5) -> 3.5489368 | H16: =IF('2-phenylethanol_DES'!G12="","",'2-phenylethanol_DES'!G12*7/$B$4) -> 3.5150374 | I16: =IF('2-phenylethanol_DES'!H12="","",'2-phenylethanol_DES'!H12*7/F16) -> 0.15466047 | N16: =IF(OR(J16="",K16=""),"",K16-J16) | O16: =IF(OR(K16="",L16=""),"",L16-K16) | P16: =IF(OR(L16="",M16=""),"",M16-L16) | Q16: =IF(OR(J16="",M16=""),"",M16-J16) | R16: =IF(Q16="","",N16/Q16) | S16: =IF(Q16="","",O16/Q16) | T16: =IF(Q16="","",P16/Q16)
A17: B2 | E17: 2 | F17: =(Componentes!AB12/(Componentes!AB12+Componentes!AB15))*Componentes!P12+(Componentes!AB15/(Componentes!AB12+Componentes!AB15))*Componentes!P15 -> 0.90566129 | G17: =IF('2-phenylethanol_DES'!I13="","",'2-phenylethanol_DES'!I13*7/$B$5) -> 3.6782648 | H17: =IF('2-phenylethanol_DES'!G13="","",'2-phenylethanol_DES'!G13*7/$B$4) -> 0.15348473 | I17: =IF('2-phenylethanol_DES'!H13="","",'2-phenylethanol_DES'!H13*7/F17) -> 3.5197817 | N17: =IF(OR(J17="",K17=""),"",K17-J17) | O17: =IF(OR(K17="",L17=""),"",L17-K17) | P17: =IF(OR(L17="",M17=""),"",M17-L17) | Q17: =IF(OR(J17="",M17=""),"",M17-J17) | R17: =IF(Q17="","",N17/Q17) | S17: =IF(Q17="","",O17/Q17) | T17: =IF(Q17="","",P17/Q17)
A18: B3 | E18: 3 | F18: =(Componentes!AB12/(Componentes!AB12+Componentes!AB15))*Componentes!P12+(Componentes!AB15/(Componentes!AB12+Componentes!AB15))*Componentes!P15 -> 0.90566129 | G18: =IF('2-phenylethanol_DES'!I14="","",'2-phenylethanol_DES'!I14*7/$B$5) -> 3.6033501 | H18: =IF('2-phenylethanol_DES'!G14="","",'2-phenylethanol_DES'!G14*7/$B$4) -> 1.8367055 | I18: =IF('2-phenylethanol_DES'!H14="","",'2-phenylethanol_DES'!H14*7/F18) -> 1.845955 | N18: =IF(OR(J18="",K18=""),"",K18-J18) | O18: =IF(OR(K18="",L18=""),"",L18-K18) | P18: =IF(OR(L18="",M18=""),"",M18-L18) | Q18: =IF(OR(J18="",M18=""),"",M18-J18) | R18: =IF(Q18="","",N18/Q18) | S18: =IF(Q18="","",O18/Q18) | T18: =IF(Q18="","",P18/Q18)
A19: B4 | E19: 4 | F19: =(Componentes!AB12/(Componentes!AB12+Componentes!AB15))*Componentes!P12+(Componentes!AB15/(Componentes!AB12+Componentes!AB15))*Componentes!P15 -> 0.90566129 | G19: =IF('2-phenylethanol_DES'!I15="","",'2-phenylethanol_DES'!I15*7/$B$5) -> 3.6382447 | H19: =IF('2-phenylethanol_DES'!G15="","",'2-phenylethanol_DES'!G15*7/$B$4) -> 0.99831742 | I19: =IF('2-phenylethanol_DES'!H15="","",'2-phenylethanol_DES'!H15*7/F19) -> 2.6823273 | N19: =IF(OR(J19="",K19=""),"",K19-J19) | O19: =IF(OR(K19="",L19=""),"",L19-K19) | P19: =IF(OR(L19="",M19=""),"",M19-L19) | Q19: =IF(OR(J19="",M19=""),"",M19-J19) | R19: =IF(Q19="","",N19/Q19) | S19: =IF(Q19="","",O19/Q19) | T19: =IF(Q19="","",P19/Q19)
A20: B5 | E20: 5 | F20: =(Componentes!AB12/(Componentes!AB12+Componentes!AB15))*Componentes!P12+(Componentes!AB15/(Componentes!AB12+Componentes!AB15))*Componentes!P15 -> 0.90566129 | G20: =IF('2-phenylethanol_DES'!I16="","",'2-phenylethanol_DES'!I16*7/$B$5) -> 3.5735807 | H20: =IF('2-phenylethanol_DES'!G16="","",'2-phenylethanol_DES'!G16*7/$B$4) -> 2.6708713 | I20: =IF('2-phenylethanol_DES'!H16="","",'2-phenylethanol_DES'!H16*7/F20) -> 1.0083461 | N20: =IF(OR(J20="",K20=""),"",K20-J20) | O20: =IF(OR(K20="",L20=""),"",L20-K20) | P20: =IF(OR(L20="",M20=""),"",M20-L20) | Q20: =IF(OR(J20="",M20=""),"",M20-J20) | R20: =IF(Q20="","",N20/Q20) | S20: =IF(Q20="","",O20/Q20) | T20: =IF(Q20="","",P20/Q20)
A22: C1 | B22: ThyCarvac | C22: Thymol | D22: Carvacrol | E22: 1 | F22: =(Componentes!AB12/(Componentes!AB12+Componentes!AB16))*Componentes!P12+(Componentes!AB16/(Componentes!AB12+Componentes!AB16))*Componentes!P16 -> 0.85403 | G22: =IF('2-phenylethanol_DES'!I18="","",'2-phenylethanol_DES'!I18*7/$B$5) -> 3.546339 | H22: =IF('2-phenylethanol_DES'!G18="","",'2-phenylethanol_DES'!G18*7/$B$4) -> 3.5140744 | I22: =IF('2-phenylethanol_DES'!H18="","",'2-phenylethanol_DES'!H18*7/F22) -> 0.16810885 | N22: =IF(OR(J22="",K22=""),"",K22-J22) | O22: =IF(OR(K22="",L22=""),"",L22-K22) | P22: =IF(OR(L22="",M22=""),"",M22-L22) | Q22: =IF(OR(J22="",M22=""),"",M22-J22) | R22: =IF(Q22="","",N22/Q22) | S22: =IF(Q22="","",O22/Q22) | T22: =IF(Q22="","",P22/Q22)
A23: C2 | E23: 2 | F23: =(Componentes!AB12/(Componentes!AB12+Componentes!AB16))*Componentes!P12+(Componentes!AB16/(Componentes!AB12+Componentes!AB16))*Componentes!P16 -> 0.85403 | G23: =IF('2-phenylethanol_DES'!I19="","",'2-phenylethanol_DES'!I19*7/$B$5) -> 3.5957673 | H23: =IF('2-phenylethanol_DES'!G19="","",'2-phenylethanol_DES'!G19*7/$B$4) -> 0.1505217 | I23: =IF('2-phenylethanol_DES'!H19="","",'2-phenylethanol_DES'!H19*7/F23) -> 3.8322424 | N23: =IF(OR(J23="",K23=""),"",K23-J23) | O23: =IF(OR(K23="",L23=""),"",L23-K23) | P23: =IF(OR(L23="",M23=""),"",M23-L23) | Q23: =IF(OR(J23="",M23=""),"",M23-J23) | R23: =IF(Q23="","",N23/Q23) | S23: =IF(Q23="","",O23/Q23) | T23: =IF(Q23="","",P23/Q23)
A24: C3 | E24: 3 | F24: =(Componentes!AB12/(Componentes!AB12+Componentes!AB16))*Componentes!P12+(Componentes!AB16/(Componentes!AB12+Componentes!AB16))*Componentes!P16 -> 0.85403 | G24: =IF('2-phenylethanol_DES'!I20="","",'2-phenylethanol_DES'!I20*7/$B$5) -> 3.5662788 | H24: =IF('2-phenylethanol_DES'!G20="","",'2-phenylethanol_DES'!G20*7/$B$4) -> 1.8259646 | I24: =IF('2-phenylethanol_DES'!H20="","",'2-phenylethanol_DES'!H20*7/F24) -> 2.0127162 | N24: =IF(OR(J24="",K24=""),"",K24-J24) | O24: =IF(OR(K24="",L24=""),"",L24-K24) | P24: =IF(OR(L24="",M24=""),"",M24-L24) | Q24: =IF(OR(J24="",M24=""),"",M24-J24) | R24: =IF(Q24="","",N24/Q24) | S24: =IF(Q24="","",O24/Q24) | T24: =IF(Q24="","",P24/Q24)
A25: C4 | E25: 4 | F25: =(Componentes!AB12/(Componentes!AB12+Componentes!AB16))*Componentes!P12+(Componentes!AB16/(Componentes!AB12+Componentes!AB16))*Componentes!P16 -> 0.85403 | G25: =IF('2-phenylethanol_DES'!I21="","",'2-phenylethanol_DES'!I21*7/$B$5) -> 3.5799699 | H25: =IF('2-phenylethanol_DES'!G21="","",'2-phenylethanol_DES'!G21*7/$B$4) -> 0.98446528 | I25: =IF('2-phenylethanol_DES'!H21="","",'2-phenylethanol_DES'!H21*7/F25) -> 2.927848 | N25: =IF(OR(J25="",K25=""),"",K25-J25) | O25: =IF(OR(K25="",L25=""),"",L25-K25) | P25: =IF(OR(L25="",M25=""),"",M25-L25) | Q25: =IF(OR(J25="",M25=""),"",M25-J25) | R25: =IF(Q25="","",N25/Q25) | S25: =IF(Q25="","",O25/Q25) | T25: =IF(Q25="","",P25/Q25)
A26: C5 | E26: 5 | F26: =(Componentes!AB12/(Componentes!AB12+Componentes!AB16))*Componentes!P12+(Componentes!AB16/(Componentes!AB12+Componentes!AB16))*Componentes!P16 -> 0.85403 | G26: =IF('2-phenylethanol_DES'!I22="","",'2-phenylethanol_DES'!I22*7/$B$5) -> 3.5550451 | H26: =IF('2-phenylethanol_DES'!G22="","",'2-phenylethanol_DES'!G22*7/$B$4) -> 2.6650194 | I26: =IF('2-phenylethanol_DES'!H22="","",'2-phenylethanol_DES'!H22*7/F26) -> 1.0975024 | N26: =IF(OR(J26="",K26=""),"",K26-J26) | O26: =IF(OR(K26="",L26=""),"",L26-K26) | P26: =IF(OR(L26="",M26=""),"",M26-L26) | Q26: =IF(OR(J26="",M26=""),"",M26-J26) | R26: =IF(Q26="","",N26/Q26) | S26: =IF(Q26="","",O26/Q26) | T26: =IF(Q26="","",P26/Q26)
A27: # | B27: DES | C27: HBA | D27: HBD | E27: TL# | F27: ρ_DES est (g/mL) | G27: V_agua est (mL) | H27: V_aroma est (mL) | I27: V_DES est (mL) | J27: W_tubo (g) | K27: W + agua (g) | L27: W + aroma (g) | M27: W + DES (g) | N27: m_water (g) | O27: m_aroma (g) | P27: m_DES (g) | Q27: m_total (g) | R27: w_water | S27: w_aroma | T27: w_DES | U27: Notas
A28: D1 | B28: ThyEug | C28: Thymol | D28: Eugenol | E28: 1 | F28: =(Componentes!AB12/(Componentes!AB12+Componentes!AB17))*Componentes!P12+(Componentes!AB17/(Componentes!AB12+Componentes!AB17))*Componentes!P17 -> 0.90154123 | G28: =IF('2-phenylethanol_DES'!I24="","",'2-phenylethanol_DES'!I24*8/$B$5) -> 4.0462187 | H28: =IF('2-phenylethanol_DES'!G24="","",'2-phenylethanol_DES'!G24*8/$B$4) -> 4.0274292 | I28: =IF('2-phenylethanol_DES'!H24="","",'2-phenylethanol_DES'!H24*8/F28) -> 0.17756259 | N28: =IF(OR(J28="",K28=""),"",K28-J28) | O28: =IF(OR(K28="",L28=""),"",L28-K28) | P28: =IF(OR(L28="",M28=""),"",M28-L28) | Q28: =IF(OR(J28="",M28=""),"",M28-J28) | R28: =IF(Q28="","",N28/Q28) | S28: =IF(Q28="","",O28/Q28) | T28: =IF(Q28="","",P28/Q28)
A29: D2 | E29: 2 | F29: =(Componentes!AB12/(Componentes!AB12+Componentes!AB17))*Componentes!P12+(Componentes!AB17/(Componentes!AB12+Componentes!AB17))*Componentes!P17 -> 0.90154123 | G29: =IF('2-phenylethanol_DES'!I25="","",'2-phenylethanol_DES'!I25*8/$B$5) -> 4.060662 | H29: =IF('2-phenylethanol_DES'!G25="","",'2-phenylethanol_DES'!G25*8/$B$4) -> 0.1762577 | I29: =IF('2-phenylethanol_DES'!H25="","",'2-phenylethanol_DES'!H25*8/F29) -> 4.1982328 | N29: =IF(OR(J29="",K29=""),"",K29-J29) | O29: =IF(OR(K29="",L29=""),"",L29-K29) | P29: =IF(OR(L29="",M29=""),"",M29-L29) | Q29: =IF(OR(J29="",M29=""),"",M29-J29) | R29: =IF(Q29="","",N29/Q29) | S29: =IF(Q29="","",O29/Q29) | T29: =IF(Q29="","",P29/Q29)
A30: D3 | E30: 3 | F30: =(Componentes!AB12/(Componentes!AB12+Componentes!AB17))*Componentes!P12+(Componentes!AB17/(Componentes!AB12+Componentes!AB17))*Componentes!P17 -> 0.90154123 | G30: =IF('2-phenylethanol_DES'!I26="","",'2-phenylethanol_DES'!I26*8/$B$5) -> 4.021986 | H30: =IF('2-phenylethanol_DES'!G26="","",'2-phenylethanol_DES'!G26*8/$B$4) -> 2.0719169 | I30: =IF('2-phenylethanol_DES'!H26="","",'2-phenylethanol_DES'!H26*8/F30) -> 2.2541842 | N30: =IF(OR(J30="",K30=""),"",K30-J30) | O30: =IF(OR(K30="",L30=""),"",L30-K30) | P30: =IF(OR(L30="",M30=""),"",M30-L30) | Q30: =IF(OR(J30="",M30=""),"",M30-J30) | R30: =IF(Q30="","",N30/Q30) | S30: =IF(Q30="","",O30/Q30) | T30: =IF(Q30="","",P30/Q30)
A31: D4 | E31: 4 | F31: =(Componentes!AB12/(Componentes!AB12+Componentes!AB17))*Componentes!P12+(Componentes!AB17/(Componentes!AB12+Componentes!AB17))*Componentes!P17 -> 0.90154123 | G31: =IF('2-phenylethanol_DES'!I27="","",'2-phenylethanol_DES'!I27*8/$B$5) -> 4.0251153 | H31: =IF('2-phenylethanol_DES'!G27="","",'2-phenylethanol_DES'!G27*8/$B$4) -> 3.0360008 | I31: =IF('2-phenylethanol_DES'!H27="","",'2-phenylethanol_DES'!H27*8/F31) -> 1.2400986 | N31: =IF(OR(J31="",K31=""),"",K31-J31) | O31: =IF(OR(K31="",L31=""),"",L31-K31) | P31: =IF(OR(L31="",M31=""),"",M31-L31) | Q31: =IF(OR(J31="",M31=""),"",M31-J31) | R31: =IF(Q31="","",N31/Q31) | S31: =IF(Q31="","",O31/Q31) | T31: =IF(Q31="","",P31/Q31)
A32: D5 | E32: 5 | F32: =(Componentes!AB12/(Componentes!AB12+Componentes!AB17))*Componentes!P12+(Componentes!AB17/(Componentes!AB12+Componentes!AB17))*Componentes!P17 -> 0.90154123 | G32: =IF('2-phenylethanol_DES'!I28="","",'2-phenylethanol_DES'!I28*8/$B$5) -> 4.0345838 | H32: =IF('2-phenylethanol_DES'!G28="","",'2-phenylethanol_DES'!G28*8/$B$4) -> 1.1234947 | I32: =IF('2-phenylethanol_DES'!H28="","",'2-phenylethanol_DES'!H28*8/F32) -> 3.2342836 | N32: =IF(OR(J32="",K32=""),"",K32-J32) | O32: =IF(OR(K32="",L32=""),"",L32-K32) | P32: =IF(OR(L32="",M32=""),"",M32-L32) | Q32: =IF(OR(J32="",M32=""),"",M32-J32) | R32: =IF(Q32="","",N32/Q32) | S32: =IF(Q32="","",O32/Q32) | T32: =IF(Q32="","",P32/Q32)
A34: E1 | B34: ThyCam | C34: Thymol | D34: Camphor | E34: 1 | F34: =(Componentes!AB12/(Componentes!AB12+Componentes!AB14))*Componentes!P12+(Componentes!AB14/(Componentes!AB12+Componentes!AB14))*Componentes!P14 -> 0.89000064 | G34: =IF('2-phenylethanol_DES'!I30="","",'2-phenylethanol_DES'!I30*7/$B$5) -> 3.5329288 | H34: =IF('2-phenylethanol_DES'!G30="","",'2-phenylethanol_DES'!G30*7/$B$4) -> 0.15037355 | I34: =IF('2-phenylethanol_DES'!H30="","",'2-phenylethanol_DES'!H30*7/F34) -> 3.7478288 | N34: =IF(OR(J34="",K34=""),"",K34-J34) | O34: =IF(OR(K34="",L34=""),"",L34-K34) | P34: =IF(OR(L34="",M34=""),"",M34-L34) | Q34: =IF(OR(J34="",M34=""),"",M34-J34) | R34: =IF(Q34="","",N34/Q34) | S34: =IF(Q34="","",O34/Q34) | T34: =IF(Q34="","",P34/Q34)
A35: E2 | E35: 2 | F35: =(Componentes!AB12/(Componentes!AB12+Componentes!AB14))*Componentes!P12+(Componentes!AB14/(Componentes!AB12+Componentes!AB14))*Componentes!P14 -> 0.89000064 | G35: =IF('2-phenylethanol_DES'!I31="","",'2-phenylethanol_DES'!I31*7/$B$5) -> 3.5404413 | H35: =IF('2-phenylethanol_DES'!G31="","",'2-phenylethanol_DES'!G31*7/$B$4) -> 3.5194819 | I35: =IF('2-phenylethanol_DES'!H31="","",'2-phenylethanol_DES'!H31*7/F35) -> 0.16210101 | N35: =IF(OR(J35="",K35=""),"",K35-J35) | O35: =IF(OR(K35="",L35=""),"",L35-K35) | P35: =IF(OR(L35="",M35=""),"",M35-L35) | Q35: =IF(OR(J35="",M35=""),"",M35-J35) | R35: =IF(Q35="","",N35/Q35) | S35: =IF(Q35="","",O35/Q35) | T35: =IF(Q35="","",P35/Q35)
A36: E3 | E36: 3 | F36: =(Componentes!AB12/(Componentes!AB12+Componentes!AB14))*Componentes!P12+(Componentes!AB14/(Componentes!AB12+Componentes!AB14))*Componentes!P14 -> 0.89000064 | G36: =IF('2-phenylethanol_DES'!I32="","",'2-phenylethanol_DES'!I32*7/$B$5) -> 3.515657 | H36: =IF('2-phenylethanol_DES'!G32="","",'2-phenylethanol_DES'!G32*7/$B$4) -> 1.8130754 | I36: =IF('2-phenylethanol_DES'!H32="","",'2-phenylethanol_DES'!H32*7/F36) -> 2.0017626 | N36: =IF(OR(J36="",K36=""),"",K36-J36) | O36: =IF(OR(K36="",L36=""),"",L36-K36) | P36: =IF(OR(L36="",M36=""),"",M36-L36) | Q36: =IF(OR(J36="",M36=""),"",M36-J36) | R36: =IF(Q36="","",N36/Q36) | S36: =IF(Q36="","",O36/Q36) | T36: =IF(Q36="","",P36/Q36)
A37: E4 | E37: 4 | F37: =(Componentes!AB12/(Componentes!AB12+Componentes!AB14))*Componentes!P12+(Componentes!AB14/(Componentes!AB12+Componentes!AB14))*Componentes!P14 -> 0.89000064 | G37: =IF('2-phenylethanol_DES'!I33="","",'2-phenylethanol_DES'!I33*7/$B$5) -> 3.5193781 | H37: =IF('2-phenylethanol_DES'!G33="","",'2-phenylethanol_DES'!G33*7/$B$4) -> 0.98016889 | I37: =IF('2-phenylethanol_DES'!H33="","",'2-phenylethanol_DES'!H33*7/F37) -> 2.881953 | N37: =IF(OR(J37="",K37=""),"",K37-J37) | O37: =IF(OR(K37="",L37=""),"",L37-K37) | P37: =IF(OR(L37="",M37=""),"",M37-L37) | Q37: =IF(OR(J37="",M37=""),"",M37-J37) | R37: =IF(Q37="","",N37/Q37) | S37: =IF(Q37="","",O37/Q37) | T37: =IF(Q37="","",P37/Q37)
A38: E5 | E38: 5 | F38: =(Componentes!AB12/(Componentes!AB12+Componentes!AB14))*Componentes!P12+(Componentes!AB14/(Componentes!AB12+Componentes!AB14))*Componentes!P14 -> 0.89000064 | G38: =IF('2-phenylethanol_DES'!I34="","",'2-phenylethanol_DES'!I34*7/$B$5) -> 3.5219759 | H38: =IF('2-phenylethanol_DES'!G34="","",'2-phenylethanol_DES'!G34*7/$B$4) -> 2.6562784 | I38: =IF('2-phenylethanol_DES'!H34="","",'2-phenylethanol_DES'!H34*7/F38) -> 1.0993138 | N38: =IF(OR(J38="",K38=""),"",K38-J38) | O38: =IF(OR(K38="",L38=""),"",L38-K38) | P38: =IF(OR(L38="",M38=""),"",M38-L38) | Q38: =IF(OR(J38="",M38=""),"",M38-J38) | R38: =IF(Q38="","",N38/Q38) | S38: =IF(Q38="","",O38/Q38) | T38: =IF(Q38="","",P38/Q38)
A40: F1 | B40: CamCar | C40: Camphor | D40: Carvone | E40: 1 | F40: =(Componentes!AB14/(Componentes!AB14+Componentes!AB13))*Componentes!P14+(Componentes!AB13/(Componentes!AB14+Componentes!AB13))*Componentes!P13 -> 0.96 | G40: =IF('2-phenylethanol_DES'!I36="","",'2-phenylethanol_DES'!I36*7/$B$5) -> 3.4987362 | H40: =IF('2-phenylethanol_DES'!G36="","",'2-phenylethanol_DES'!G36*7/$B$4) -> 0.15222544 | I40: =IF('2-phenylethanol_DES'!H36="","",'2-phenylethanol_DES'!H36*7/F40) -> 3.5082396 | N40: =IF(OR(J40="",K40=""),"",K40-J40) | O40: =IF(OR(K40="",L40=""),"",L40-K40) | P40: =IF(OR(L40="",M40=""),"",M40-L40) | Q40: =IF(OR(J40="",M40=""),"",M40-J40) | R40: =IF(Q40="","",N40/Q40) | S40: =IF(Q40="","",O40/Q40) | T40: =IF(Q40="","",P40/Q40)
A41: F2 | E41: 2 | F41: =(Componentes!AB14/(Componentes!AB14+Componentes!AB13))*Componentes!P14+(Componentes!AB13/(Componentes!AB14+Componentes!AB13))*Componentes!P13 -> 0.96 | G41: =IF('2-phenylethanol_DES'!I37="","",'2-phenylethanol_DES'!I37*7/$B$5) -> 3.534333 | H41: =IF('2-phenylethanol_DES'!G37="","",'2-phenylethanol_DES'!G37*7/$B$4) -> 3.5260006 | I41: =IF('2-phenylethanol_DES'!H37="","",'2-phenylethanol_DES'!H37*7/F41) -> 0.15028125 | N41: =IF(OR(J41="",K41=""),"",K41-J41) | O41: =IF(OR(K41="",L41=""),"",L41-K41) | P41: =IF(OR(L41="",M41=""),"",M41-L41) | Q41: =IF(OR(J41="",M41=""),"",M41-J41) | R41: =IF(Q41="","",N41/Q41) | S41: =IF(Q41="","",O41/Q41) | T41: =IF(Q41="","",P41/Q41)
A42: F3 | E42: 3 | F42: =(Componentes!AB14/(Componentes!AB14+Componentes!AB13))*Componentes!P14+(Componentes!AB13/(Componentes!AB14+Componentes!AB13))*Componentes!P13 -> 0.96 | G42: =IF('2-phenylethanol_DES'!I38="","",'2-phenylethanol_DES'!I38*7/$B$5) -> 3.473671 | H42: =IF('2-phenylethanol_DES'!G38="","",'2-phenylethanol_DES'!G38*7/$B$4) -> 1.8068531 | I42: =IF('2-phenylethanol_DES'!H38="","",'2-phenylethanol_DES'!H38*7/F42) -> 1.9055312 | N42: =IF(OR(J42="",K42=""),"",K42-J42) | O42: =IF(OR(K42="",L42=""),"",L42-K42) | P42: =IF(OR(L42="",M42=""),"",M42-L42) | Q42: =IF(OR(J42="",M42=""),"",M42-J42) | R42: =IF(Q42="","",N42/Q42) | S42: =IF(Q42="","",O42/Q42) | T42: =IF(Q42="","",P42/Q42)
A43: F4 | E43: 4 | F43: =(Componentes!AB14/(Componentes!AB14+Componentes!AB13))*Componentes!P14+(Componentes!AB13/(Componentes!AB14+Componentes!AB13))*Componentes!P13 -> 0.96 | G43: =IF('2-phenylethanol_DES'!I39="","",'2-phenylethanol_DES'!I39*7/$B$5) -> 3.490662 | H43: =IF('2-phenylethanol_DES'!G39="","",'2-phenylethanol_DES'!G39*7/$B$4) -> 2.6525747 | I43: =IF('2-phenylethanol_DES'!H39="","",'2-phenylethanol_DES'!H39*7/F43) -> 1.0553958 | N43: =IF(OR(J43="",K43=""),"",K43-J43) | O43: =IF(OR(K43="",L43=""),"",L43-K43) | P43: =IF(OR(L43="",M43=""),"",M43-L43) | Q43: =IF(OR(J43="",M43=""),"",M43-J43) | R43: =IF(Q43="","",N43/Q43) | S43: =IF(Q43="","",O43/Q43) | T43: =IF(Q43="","",P43/Q43)
A44: F5 | E44: 5 | F44: =(Componentes!AB14/(Componentes!AB14+Componentes!AB13))*Componentes!P14+(Componentes!AB13/(Componentes!AB14+Componentes!AB13))*Componentes!P13 -> 0.96 | G44: =IF('2-phenylethanol_DES'!I40="","",'2-phenylethanol_DES'!I40*7/$B$5) -> 3.4750752 | H44: =IF('2-phenylethanol_DES'!G40="","",'2-phenylethanol_DES'!G40*7/$B$4) -> 0.97876146 | I44: =IF('2-phenylethanol_DES'!H40="","",'2-phenylethanol_DES'!H40*7/F44) -> 2.7192083 | N44: =IF(OR(J44="",K44=""),"",K44-J44) | O44: =IF(OR(K44="",L44=""),"",L44-K44) | P44: =IF(OR(L44="",M44=""),"",M44-L44) | Q44: =IF(OR(J44="",M44=""),"",M44-J44) | R44: =IF(Q44="","",N44/Q44) | S44: =IF(Q44="","",O44/Q44) | T44: =IF(Q44="","",P44/Q44)
A45: # | B45: DES | C45: HBA | D45: HBD | E45: TL# | F45: ρ_DES est (g/mL) | G45: V_agua est (mL) | H45: V_aroma est (mL) | I45: V_DES est (mL) | J45: W_tubo (g) | K45: W + agua (g) | L45: W + aroma (g) | M45: W + DES (g) | N45: m_water (g) | O45: m_aroma (g) | P45: m_DES (g) | Q45: m_total (g) | R45: w_water | S45: w_aroma | T45: w_DES | U45: Notas
A46: H1 | B46: CamCarvac | C46: Camphor | D46: Carvacrol | E46: 1 | F46: =(Componentes!AB14/(Componentes!AB14+Componentes!AB16))*Componentes!P14+(Componentes!AB16/(Componentes!AB14+Componentes!AB16))*Componentes!P16 -> 0.92473709 | G46: =IF('2-phenylethanol_DES'!I48="","",'2-phenylethanol_DES'!I48*8/$B$5) -> 4.021665 | H46: =IF('2-phenylethanol_DES'!G48="","",'2-phenylethanol_DES'!G48*8/$B$4) -> 0.17227878 | I46: =IF('2-phenylethanol_DES'!H48="","",'2-phenylethanol_DES'!H48*8/F46) -> 4.1391224 | N46: =IF(OR(J46="",K46=""),"",K46-J46) | O46: =IF(OR(K46="",L46=""),"",L46-K46) | P46: =IF(OR(L46="",M46=""),"",M46-L46) | Q46: =IF(OR(J46="",M46=""),"",M46-J46) | R46: =IF(Q46="","",N46/Q46) | S46: =IF(Q46="","",O46/Q46) | T46: =IF(Q46="","",P46/Q46)
A47: H2 | E47: 2 | F47: =(Componentes!AB14/(Componentes!AB14+Componentes!AB16))*Componentes!P14+(Componentes!AB16/(Componentes!AB14+Componentes!AB16))*Componentes!P16 -> 0.92473709 | G47: =IF('2-phenylethanol_DES'!I49="","",'2-phenylethanol_DES'!I49*8/$B$5) -> 4.0460582 | H47: =IF('2-phenylethanol_DES'!G49="","",'2-phenylethanol_DES'!G49*8/$B$4) -> 4.022265 | I47: =IF('2-phenylethanol_DES'!H49="","",'2-phenylethanol_DES'!H49*8/F47) -> 0.17855886 | N47: =IF(OR(J47="",K47=""),"",K47-J47) | O47: =IF(OR(K47="",L47=""),"",L47-K47) | P47: =IF(OR(L47="",M47=""),"",M47-L47) | Q47: =IF(OR(J47="",M47=""),"",M47-J47) | R47: =IF(Q47="","",N47/Q47) | S47: =IF(Q47="","",O47/Q47) | T47: =IF(Q47="","",P47/Q47)
A48: H3 | E48: 3 | F48: =(Componentes!AB14/(Componentes!AB14+Componentes!AB16))*Componentes!P14+(Componentes!AB16/(Componentes!AB14+Componentes!AB16))*Componentes!P16 -> 0.92473709 | G48: =IF('2-phenylethanol_DES'!I50="","",'2-phenylethanol_DES'!I50*8/$B$5) -> 4.0119559 | H48: =IF('2-phenylethanol_DES'!G50="","",'2-phenylethanol_DES'!G50*8/$B$4) -> 2.0677686 | I48: =IF('2-phenylethanol_DES'!H50="","",'2-phenylethanol_DES'!H50*8/F48) -> 2.2126938 | N48: =IF(OR(J48="",K48=""),"",K48-J48) | O48: =IF(OR(K48="",L48=""),"",L48-K48) | P48: =IF(OR(L48="",M48=""),"",M48-L48) | Q48: =IF(OR(J48="",M48=""),"",M48-J48) | R48: =IF(Q48="","",N48/Q48) | S48: =IF(Q48="","",O48/Q48) | T48: =IF(Q48="","",P48/Q48)
...

Sheet Sheet2
A1: BINARIOS TERPENOS CON AGUA | H1: V_sample: | I1: 300 | J1: µL | K1: +700 µL IPA
E2: solo pesar viales GC!!
A3: System | B3: Phase | C3: Rep | D3: GC Vial ID | E3: W_vial (g) | F3: W + muestra (g) | G3: W +solvente (IPA) (g) | H3: KF w_water (%) | I3: Notes
A4: BIN1 | B4: Top | C4: 1 | D4: BIN1-T1
C5: 2 | D5: BIN1-T2
B6: Bot | C6: 1 | D6: BIN1-B1
C7: 2 | D7: BIN1-B2
A8: BIN2 | B8: Top | C8: 1 | D8: BIN2-T1
C9: 2 | D9: BIN2-T2
B10: Bot | C10: 1 | D10: BIN2-B1
C11: 2 | D11: BIN2-B2
A12: BIN3 | B12: Top | C12: 1 | D12: BIN3-T1
C13: 2 | D13: BIN3-T2
B14: Bot | C14: 1 | D14: BIN3-B1
C15: 2 | D15: BIN3-B2
A19: System | B19: Phase | C19: Rep | D19: GC Vial ID | E19: W_vial (g) | F19: W + muestra (g) | G19: W +solvente (IPA) (g) | H19: KF w_water (%) | I19: Notes
A20: BIN4 | B20: Top | C20: 1 | D20: BIN4-T1
C21: 2 | D21: BIN4-T2
B22: Bot | C22: 1 | D22: BIN4-B1
C23: 2 | D23: BIN4-B2
A24: BIN5 | B24: Top | C24: 1 | D24: BIN5-T1
C25: 2 | D25: BIN5-T2
B26: Bot | C26: 1 | D26: BIN5-B1
C27: 2 | D27: BIN5-B2
A28: BIN6 | B28: Top | C28: 1 | D28: BIN6-T1
C29: 2 | D29: BIN6-T2
B30: Bot | C30: 1 | D30: BIN6-B1
C31: 2 | D31: BIN6-B2
A34: System | B34: Phase | C34: Rep | D34: GC Vial ID | E34: W_vial (g) | F34: W + muestra (g) | G34: W +solvente (IPA) (g) | H34: KF w_water (%) | I34: Notes
A35: BIN7 | B35: Top | C35: 1 | D35: BIN7-T1
C36: 2 | D36: BIN7-T2
B37: Bot | C37: 1 | D37: BIN7-B1
C38: 2 | D38: BIN7-B2
A39: BIN8 | B39: Top | C39: 1 | D39: BIN8-T1
C40: 2 | D40: BIN8-T2
B41: Bot | C41: 1 | D41: BIN8-B1
C42: 2 | D42: BIN8-B2
