Workbook

Sheet Componentes
A1: IDENTIFICADOR | G1: INVENTARIO | M1: PROPIEDADES | S1: SEGURIDAD | V1: METADATA
A2: ID | B2: Chemical Name | C2: Common Name(s) | D2: CAS Number | E2: Formula | F2: Canonical SMILES | G2: Location | H2: Supplier | I2: Grade/Purity | J2: Lot Number | K2: Quantity | L2: Unit | M2: MW | N2: Tb | O2: Tm | P2: ρ (25°C) | Q2: η (25°C) | R2: Pᵛᵃᵖ (25°C) | S2: Flash Point | T2: Hazard Class | U2: Storage | V2: Date Received | W2: Status | X2: Notes | AA2: comp_id | AB2: MW | AC2: purity
A3: Internal component code | B3: IUPAC or standard name | C3: Alternative names | D3: CAS registry number | E3: Molecular formula | F3: For modeling/databases | G3: Lab position (e.g., 3.1) | H3: Vendor name | I3: (Según batch) | J3: Batch identifier | K3: Amount available | L3: mL, g, kg, etc. | M3: g/mol | N3: °C (1 atm) | O3: °C | P3: g/cm³ | Q3: mPa·s | R3: kPa | S3: °C | T3: GHS classification | U3: Requirements | V3: YYYY-MM-DD | W3: Active/Depleted | X3: Additional info | AA3: beta | AB3: 192.3 | AC3: 0.978
A4: beta | B4: b-ionone (trans) | C4: - | D4: 14901-07-6 | E4: C13H20O | F4: CC1=C(C(CCC1)(C)C)/C=C/C(=O)C | G4: REFRIGERADOR | H4: Sigma-Aldrich | I4: 97.8% (GC) | J4: SHBL2869 | K4: 1 | L4: L | M4: 192.3 | N4: 266 | O4: - | P4: 0.94498 | R4: - | S4: - | T4: - | U4: - | V4: - | W4: Active | AA4: 2pe | AB4: 122.16 | AC4: 1
A5: 2pe | B5: 2-phenylethanol | C5: - | D5: 60-12-8 | E5: C8H10O | F5: OCCc1ccccc1 | G5: 3.x | H5: Sigma-Aldrich | I5: > 99.9% (GC) | J5: SDBB2371 | K5: 1 | L5: L | M5: 122.16 | N5: 219 | O5: - | P5: 1.01985 | R5: - | S5: - | T5: - | U5: - | V5: - | W5: Active | AA5: gamma | AB5: 170.25 | AC5: 0.987
A6: gamma | B6: g-decalactone | C6: - | D6: 706-14-9 | E6: C10H18O2 | F6: CCCCCCC1CCC(=O)O1 | G6: 3.x | H6: Sigma-Aldrich | I6: 98.7% (GC) | J6: SHBR4960 | K6: 1 | L6: L | M6: 170.25 | N6: 285 | O6: - | P6: 0.95292 | R6: - | S6: - | T6: - | U6: - | V6: - | W6: Active | AA6: 2m3b2oh | AB6: 86.13 | AC6: 0.996
A7: 2m3b2oh | B7: 2-methyl-3-buten-2-ol | C7: 2M3B2OH | D7: 115-18-4 | E7: C5H10O | F7: CC(C)(C=C)O | G7: REFRIGERADOR | H7: Aldrich | I7: 99.6% (GC) | J7: STBH5331 | K7: 1 | L7: L | M7: 86.13 | N7: 99 | O7: - | P7: 0.82388 | R7: - | S7: - | T7: - | U7: - | V7: - | W7: Active | AA7: 2m2boh | AB7: 88.15 | AC7: 1
A8: 2m2boh | B8: 2-methyl-2-butanol | C8: tert-amyl alcohol | D8: 75-85-4 | E8: C5H12O | F8: CCC(C)(C)O | G8: 3.2 | H8: Sigma-Aldrich | I8: >99.9% (GC) | J8: SDBB4598 | K8: 1 | L8: L | M8: 88.15 | N8: 102 | O8: - | P8: 0.80899 | R8: - | S8: - | T8: - | U8: - | V8: - | W8: Active | AA8: hexoh | AB8: 102.17 | AC8: 0.998
A9: hexoh | B9: 1-hexanol | C9: - | D9: 111-27-3 | E9: C6H18O | F9: CCCCCCO | G9: 1.3. | H9: Sigma-Aldrich | I9: 99.8% (GC) | J9: SHBC9189V | K9: 700 | L9: mL | M9: 102.17 | N9: 156 | O9: - | P9: 0.81883 | R9: - | S9: - | T9: - | U9: - | V9: - | W9: Active | AA9: octoh | AB9: 130.23 | AC9: 0.997
A10: octoh | B10: 1-octanol | C10: - | D10: 111-87-5 | E10: C8H18O | F10: CCCCCCCCO | G10: 1.2 | H10: Sigma-Aldrich | I10: 99.7% (GC) | J10: SDBB1117 | K10: 200? | L10: mL | M10: 130.23 | N10: 195 | O10: - | P10: 0.82518 | R10: - | S10: - | T10: - | U10: - | V10: - | W10: Active | AA10: mibk | AB10: 100.16 | AC10: 0.998
A11: mibk | B11: methyl isobutyl ketone | C11: MIBK | D11: 108-10-1 | E11: C6H12O | F11: CC(C)CC(=O)C | G11: 2.4 | H11: Merck Millipor | I11: 99.8% (GC) | J11: K51239346927 | K11: 300? | L11: mL | M11: 100.16 | N11: 115 | O11: - | P11: 0.80143 | R11: - | S11: - | T11: - | U11: - | V11: - | W11: Active | AA11: 2octanone | AB11: 128.21 | AC11: 0.988
A12: 2octanone | B12: 2-octanone | C12: Hexyl methyl ketone | D12: 111-13-7 | E12: C8H16O | F12: CCCCCCC(=O)C | G12: 3.2 | H12: Sigma-Aldrich | I12: 98.8% (GC) | J12: SHBQ4121 | K12: 200? | L12: mL | M12: 128.21 | N12: 173 | O12: - | P12: 0.81906 | R12: - | S12: - | T12: - | U12: - | V12: - | W12: Active | AA12: thymol | AB12: 150.22 | AC12: 0.999
A13: thymol | B13: Thymol | C13: - | D13: 89-83-8 | E13: C10H14O | F13: Cc1ccc(C(C)C)c(O)c1 | G13: 1.2 | H13: Sigma-Aldrich | I13: >99.9% (GC) | J13: SHBQ5769 | K13: 800 | L13: g | M13: 150.22 | N13: 233 | O13: - | P13: 0.96 | R13: - | S13: - | T13: - | U13: - | V13: - | W13: Active | AA13: carvone | AB13: 150.22 | AC13: 0.992
A14: carvone | B14: L-Carvone | C14: (-)-Carvone | D14: 6485-40-1 | E14: C10H14O | F14: C=C(C)[C@@H]1CC=C(C)C(=O)C1 | G14: 1.2 | H14: Sigma-Aldrich | I14: 99.2% (GC) | J14: SHBQ8402 | K14: 1 | L14: kg | M14: 150.22 | N14: 226 | O14: - | P14: 0.96 | R14: - | S14: - | T14: - | U14: - | V14: - | W14: Active | AA14: camphor | AB14: 152.24 | AC14: 0.969
A15: camphor | B15: DL-Camphor | C15: - | D15: 76-22-2 | E15: C10H16O | F15: CC1(C)C2CCC1(C)C(=O)C2 | G15: 3.2 | H15: Sigma-Aldrich | I15: 96.9% (GC) | J15: SDBB0718 | K15: 250 | L15: g | M15: 152.24 | N15: 210 | O15: - | P15: 0.99 | R15: - | S15: - | T15: - | U15: - | V15: - | W15: Active | AA15: geraniol | AB15: 154.25 | AC15: 0.989
A16: geraniol | B16: Geraniol | C16: - | D16: 106-24-1 | E16: C10H18O | F16: CC(C)=CCC/C(C)=C/CO | G16: 2.3 | H16: Sigma-Aldrich | I16: 98.9% (GC) | J16: SHBP7700 | K16: 700 | L16: g | M16: 154.25 | N16: 229 | O16: - | P16: 0.889 | R16: - | S16: - | T16: - | U16: - | V16: - | W16: Active | AA16: carvacrol | AB16: 150.22 | AC16: 0.997
A17: carvacrol | B17: Carvacrol | C17: - | D17: 499-75-2 | E17: C10H14O | F17: Cc1ccc(C(C)C)cc1O | G17: 2.1 | H17: Sigma-Aldrich | I17: 99.7% (GC) | J17: SHBQ9085 | K17: 400? | L17: mL | M17: 150.22 | N17: 239 | O17: - | P17: 0.977 | R17: - | S17: - | T17: - | U17: - | V17: - | W17: Active | AA17: eugenol | AB17: 164.2 | AC17: 0.992
A18: eugenol | B18: Eugenol | C18: - | D18: 97-53-0 | E18: C10H12O2 | F18: C=CCc1ccc(O)c(OC)c1 | G18: 1.3 | H18: Sigma-Aldrich | I18: 99.2% (GC) | J18: SHBM4053 | K18: 500? | L18: mL | M18: 164.2 | N18: 215 | O18: - | P18: 1.06 | R18: - | S18: - | T18: - | U18: - | V18: - | W18: Active
A19: h2o | B19: Water | C19: - | D19: - | E19: - | G19: - | H19: - | I19: HPLC | J19: - | K19: - | L19: - | M19: 18.02 | N19: 100 | O19: - | R19: - | S19: - | T19: - | U19: - | V19: - | W19: Active
B21: Aroma (soluto)
B22: Solventes
B23: DESs
B24: Agua (diluyente)

Sheet datos_des
B2: LLE con agua | C2: ThyCar | D2: ThyGer | E2: ThyCarvon | F2: ThyEug | G2: CamCar | H2: CamGer | I2: CamCarvac | J2: CamEug
B3: b-ionona | L3: HBA | M3: HBD
B4: 2-phenylethanol | K4: 1 | L4: Thymol | M4: Carvone | N4: 1
B5: g-decalactone | K5: 2 | L5: Camphor | M5: Geraniol | N5: 2
M6: Carvacrol | N6: 3
B7: VLE | C7: ThyCar | D7: ThyGer | E7: ThyCarvon | F7: ThyEug | G7: CamCar | H7: CamGer | I7: CamCarvac | J7: CamEug | M7: Eugenol | N7: 4
B8: b-ionona
B9: 2-phenylethanol
B10: g-decalactone
C12: Falta fleck
B14: PREPARACIÓN DES 10.00 g (1:1 molar)
B15: m_total: | C15: 10 | D15: g
B16: DES | C16: HBA | D16: MW_HBA | E16: Pureza_HBA | F16: m_HBA target (g) | G16: m_HBA exp (g) | H16: HBD | I16: MW_HBD | J16: Pureza_HBD | K16: m_HBD target (g) | L16: m_HBD exp (g) | M16: n_HBA/n_HBD
B17: ThyCar | C17: thymol | D17: =VLOOKUP(C17,Componentes!$AA$3:$AC$17,2,FALSE()) -> 150.22 | E17: =VLOOKUP(C17,Componentes!$AA$3:$AC$17,3,FALSE()) -> 0.999 | F17: =$C$15*D17/(D17+I17)/E17 -> 5.005005 | G17: 5.0064 | H17: carvone | I17: =VLOOKUP(H17,Componentes!$AA$3:$AC$17,2,FALSE()) -> 150.22 | J17: =VLOOKUP(H17,Componentes!$AA$3:$AC$17,3,FALSE()) -> 0.992 | K17: =$C$15*I17/(D17+I17)/J17 -> 5.0403226 | L17: 5.0469 | M17: =IF(AND(G17<>"",L17<>""),(G17*E17/D17)/(L17*J17/I17),"") -> 0.9989751
B18: ThyGer | C18: thymol | D18: =VLOOKUP(C18,Componentes!$AA$3:$AC$17,2,FALSE()) -> 150.22 | E18: =VLOOKUP(C18,Componentes!$AA$3:$AC$17,3,FALSE()) -> 0.999 | F18: =$C$15*D18/(D18+I18)/E18 -> 4.9387582 | G18: 4.95 | H18: geraniol | I18: =VLOOKUP(H18,Componentes!$AA$3:$AC$17,2,FALSE()) -> 154.25 | J18: =VLOOKUP(H18,Componentes!$AA$3:$AC$17,3,FALSE()) -> 0.989 | K18: =$C$15*I18/(D18+I18)/J18 -> 5.1225284 | L18: 5.1232 | M18: =IF(AND(G18<>"",L18<>""),(G18*E18/D18)/(L18*J18/I18),"") -> 1.0021449
B19: ThyCarvac | C19: thymol | D19: =VLOOKUP(C19,Componentes!$AA$3:$AC$17,2,FALSE()) -> 150.22 | E19: =VLOOKUP(C19,Componentes!$AA$3:$AC$17,3,FALSE()) -> 0.999 | F19: =$C$15*D19/(D19+I19)/E19 -> 5.005005 | G19: 5.0063 | H19: carvacrol | I19: =VLOOKUP(H19,Componentes!$AA$3:$AC$17,2,FALSE()) -> 150.22 | J19: =VLOOKUP(H19,Componentes!$AA$3:$AC$17,3,FALSE()) -> 0.997 | K19: =$C$15*I19/(D19+I19)/J19 -> 5.0150451 | L19: 5.0156 | M19: =IF(AND(G19<>"",L19<>""),(G19*E19/D19)/(L19*J19/I19),"") -> 1.0001481
B20: ThyEug | C20: thymol | D20: =VLOOKUP(C20,Componentes!$AA$3:$AC$17,2,FALSE()) -> 150.22 | E20: =VLOOKUP(C20,Componentes!$AA$3:$AC$17,3,FALSE()) -> 0.999 | F20: =$C$15*D20/(D20+I20)/E20 -> 4.7824684 | G20: 4.7931 | H20: eugenol | I20: =VLOOKUP(H20,Componentes!$AA$3:$AC$17,2,FALSE()) -> 164.2 | J20: =VLOOKUP(H20,Componentes!$AA$3:$AC$17,3,FALSE()) -> 0.992 | K20: =$C$15*I20/(D20+I20)/J20 -> 5.2644295 | L20: 5.2668 | M20: =IF(AND(G20<>"",L20<>""),(G20*E20/D20)/(L20*J20/I20),"") -> 1.001772
B21: ThyCam | C21: thymol | D21: =VLOOKUP(C21,Componentes!$AA$3:$AC$17,2,FALSE()) -> 150.22 | E21: =VLOOKUP(C21,Componentes!$AA$3:$AC$17,3,FALSE()) -> 0.999 | F21: =$C$15*D21/(D21+I21)/E21 -> 4.9715787 | G21: =1.6711+1.6663+1.6953 -> 5.0327 | H21: camphor | I21: =VLOOKUP(H21,Componentes!$AA$3:$AC$17,2,FALSE()) -> 152.24 | J21: =VLOOKUP(H21,Componentes!$AA$3:$AC$17,3,FALSE()) -> 0.969 | K21: =$C$15*I21/(D21+I21)/J21 -> 5.1944199 | L21: =1.7344+1.7354+1.7709 -> 5.2407 | M21: =IF(AND(G21<>"",L21<>""),(G21*E21/D21)/(L21*J21/I21),"") -> 1.0033547
B22: CamCar | C22: camphor | D22: =VLOOKUP(C22,Componentes!$AA$3:$AC$17,2,FALSE()) -> 152.24 | E22: =VLOOKUP(C22,Componentes!$AA$3:$AC$17,3,FALSE()) -> 0.969 | F22: =$C$15*D22/(D22+I22)/E22 -> 5.1944199 | G22: 5.2014 | H22: carvone | I22: =VLOOKUP(H22,Componentes!$AA$3:$AC$17,2,FALSE()) -> 150.22 | J22: =VLOOKUP(H22,Componentes!$AA$3:$AC$17,3,FALSE()) -> 0.992 | K22: =$C$15*I22/(D22+I22)/J22 -> 5.0066604 | L22: 5.0074 | M22: =IF(AND(G22<>"",L22<>""),(G22*E22/D22)/(L22*J22/I22),"") -> 1.0011959
B23: CamGer | C23: camphor | D23: =VLOOKUP(C23,Componentes!$AA$3:$AC$17,2,FALSE()) -> 152.24 | E23: =VLOOKUP(C23,Componentes!$AA$3:$AC$17,3,FALSE()) -> 0.969 | F23: =$C$15*D23/(D23+I23)/E23 -> 5.1261191 | G23: 5.1236 | H23: geraniol | I23: =VLOOKUP(H23,Componentes!$AA$3:$AC$17,2,FALSE()) -> 154.25 | J23: =VLOOKUP(H23,Componentes!$AA$3:$AC$17,3,FALSE()) -> 0.989 | K23: =$C$15*I23/(D23+I23)/J23 -> 5.0887671 | L23: 5.084 | M23: =IF(AND(G23<>"",L23<>""),(G23*E23/D23)/(L23*J23/I23),"") -> 1.0004458
B24: CamCarvac | C24: camphor | D24: =VLOOKUP(C24,Componentes!$AA$3:$AC$17,2,FALSE()) -> 152.24 | E24: =VLOOKUP(C24,Componentes!$AA$3:$AC$17,3,FALSE()) -> 0.969 | F24: =$C$15*D24/(D24+I24)/E24 -> 5.1944199 | G24: 5.1992 | H24: carvacrol | I24: =VLOOKUP(H24,Componentes!$AA$3:$AC$17,2,FALSE()) -> 150.22 | J24: =VLOOKUP(H24,Componentes!$AA$3:$AC$17,3,FALSE()) -> 0.997 | K24: =$C$15*I24/(D24+I24)/J24 -> 4.9815518 | L24: 4.9816 | M24: =IF(AND(G24<>"",L24<>""),(G24*E24/D24)/(L24*J24/I24),"") -> 1.0009106
B25: CamEug | C25: camphor | D25: =VLOOKUP(C25,Componentes!$AA$3:$AC$17,2,FALSE()) -> 152.24 | E25: =VLOOKUP(C25,Componentes!$AA$3:$AC$17,3,FALSE()) -> 0.969 | F25: =$C$15*D25/(D25+I25)/E25 -> 4.9649356 | G25: 4.9655 | H25: eugenol | I25: =VLOOKUP(H25,Componentes!$AA$3:$AC$17,2,FALSE()) -> 164.2 | J25: =VLOOKUP(H25,Componentes!$AA$3:$AC$17,3,FALSE()) -> 0.992 | K25: =$C$15*I25/(D25+I25)/J25 -> 5.230824 | L25: 5.2307 | M25: =IF(AND(G25<>"",L25<>""),(G25*E25/D25)/(L25*J25/I25),"") -> 1.0001374
B27: Amarillo: ingreso experimental | E27: Verde: calculado desde Componentes

Sheet Lab_DES
A1: LAB SHEET — 2-phenylethanol + DES + Water
A2: Add in order: tube → water → aroma → DES. Record cumulative balance reading after each addition.
A4: ρ_aroma (g/mL): | B4: =Componentes!P4 -> 0.94498 | C4: 2-phenylethanol
A5: ρ_water (g/mL): | B5: 0.997
B7: Pipetting guide (from predictions) | F7: Record on balance | J7: Auto-calculated by difference
A9: # | B9: DES | C9: HBA | D9: HBD | E9: TL# | F9: ρ_DES est (g/mL) | G9: V_water est (mL) | H9: V_aroma est (mL) | I9: V_DES est (mL) | J9: W_tube (g) | K9: W +water (g) | L9: W +aroma (g) | M9: W +DES (g) | N9: m_water (g) | O9: m_aroma (g) | P9: m_DES (g) | Q9: m_total (g) | R9: w_water | S9: w_aroma | T9: w_DES | U9: Notes
A10: 1 | B10: ThyCar | C10: Thymol | D10: Carvone | E10: 1 | F10: =(Componentes!AB12/(Componentes!AB12+Componentes!AB13))*Componentes!P12+(Componentes!AB13/(Componentes!AB12+Componentes!AB13))*Componentes!P13 -> 0.88953 | G10: =IF(#REF!="","",#REF!*7/$B$5) -> #REF! | H10: =IF(#REF!="","",#REF!*7/$B$4) -> #REF! | I10: =IF(#REF!="","",#REF!*7/F10) -> #REF! | N10: =IF(OR(J10="",K10=""),"",K10-J10) | O10: =IF(OR(K10="",L10=""),"",L10-K10) | P10: =IF(OR(L10="",M10=""),"",M10-L10) | Q10: =IF(OR(J10="",M10=""),"",M10-J10) | R10: =IF(Q10="","",N10/Q10) | S10: =IF(Q10="","",O10/Q10) | T10: =IF(Q10="","",P10/Q10)
A11: 2 | E11: 2 | F11: =(Componentes!AB12/(Componentes!AB12+Componentes!AB13))*Componentes!P12+(Componentes!AB13/(Componentes!AB12+Componentes!AB13))*Componentes!P13 -> 0.88953 | G11: =IF(#REF!="","",#REF!*7/$B$5) -> #REF! | H11: =IF(#REF!="","",#REF!*7/$B$4) -> #REF! | I11: =IF(#REF!="","",#REF!*7/F11) -> #REF! | N11: =IF(OR(J11="",K11=""),"",K11-J11) | O11: =IF(OR(K11="",L11=""),"",L11-K11) | P11: =IF(OR(L11="",M11=""),"",M11-L11) | Q11: =IF(OR(J11="",M11=""),"",M11-J11) | R11: =IF(Q11="","",N11/Q11) | S11: =IF(Q11="","",O11/Q11) | T11: =IF(Q11="","",P11/Q11)
A12: 3 | E12: 3 | F12: =(Componentes!AB12/(Componentes!AB12+Componentes!AB13))*Componentes!P12+(Componentes!AB13/(Componentes!AB12+Componentes!AB13))*Componentes!P13 -> 0.88953 | G12: =IF(#REF!="","",#REF!*7/$B$5) -> #REF! | H12: =IF(#REF!="","",#REF!*7/$B$4) -> #REF! | I12: =IF(#REF!="","",#REF!*7/F12) -> #REF! | N12: =IF(OR(J12="",K12=""),"",K12-J12) | O12: =IF(OR(K12="",L12=""),"",L12-K12) | P12: =IF(OR(L12="",M12=""),"",M12-L12) | Q12: =IF(OR(J12="",M12=""),"",M12-J12) | R12: =IF(Q12="","",N12/Q12) | S12: =IF(Q12="","",O12/Q12) | T12: =IF(Q12="","",P12/Q12)
A13: 4 | E13: 4 | F13: =(Componentes!AB12/(Componentes!AB12+Componentes!AB13))*Componentes!P12+(Componentes!AB13/(Componentes!AB12+Componentes!AB13))*Componentes!P13 -> 0.88953 | G13: =IF(#REF!="","",#REF!*7/$B$5) -> #REF! | H13: =IF(#REF!="","",#REF!*7/$B$4) -> #REF! | I13: =IF(#REF!="","",#REF!*7/F13) -> #REF! | N13: =IF(OR(J13="",K13=""),"",K13-J13) | O13: =IF(OR(K13="",L13=""),"",L13-K13) | P13: =IF(OR(L13="",M13=""),"",M13-L13) | Q13: =IF(OR(J13="",M13=""),"",M13-J13) | R13: =IF(Q13="","",N13/Q13) | S13: =IF(Q13="","",O13/Q13) | T13: =IF(Q13="","",P13/Q13)
A14: 5 | E14: 5 | F14: =(Componentes!AB12/(Componentes!AB12+Componentes!AB13))*Componentes!P12+(Componentes!AB13/(Componentes!AB12+Componentes!AB13))*Componentes!P13 -> 0.88953 | G14: =IF(#REF!="","",#REF!*7/$B$5) -> #REF! | H14: =IF(#REF!="","",#REF!*7/$B$4) -> #REF! | I14: =IF(#REF!="","",#REF!*7/F14) -> #REF! | N14: =IF(OR(J14="",K14=""),"",K14-J14) | O14: =IF(OR(K14="",L14=""),"",L14-K14) | P14: =IF(OR(L14="",M14=""),"",M14-L14) | Q14: =IF(OR(J14="",M14=""),"",M14-J14) | R14: =IF(Q14="","",N14/Q14) | S14: =IF(Q14="","",O14/Q14) | T14: =IF(Q14="","",P14/Q14)
A16: 6 | B16: ThyGer | C16: Thymol | D16: Geraniol | E16: 1 | F16: =(Componentes!AB12/(Componentes!AB12+Componentes!AB15))*Componentes!P12+(Componentes!AB15/(Componentes!AB12+Componentes!AB15))*Componentes!P15 -> 0.90566129 | G16: =IF(#REF!="","",#REF!*7/$B$5) -> #REF! | H16: =IF(#REF!="","",#REF!*7/$B$4) -> #REF! | I16: =IF(#REF!="","",#REF!*7/F16) -> #REF! | N16: =IF(OR(J16="",K16=""),"",K16-J16) | O16: =IF(OR(K16="",L16=""),"",L16-K16) | P16: =IF(OR(L16="",M16=""),"",M16-L16) | Q16: =IF(OR(J16="",M16=""),"",M16-J16) | R16: =IF(Q16="","",N16/Q16) | S16: =IF(Q16="","",O16/Q16) | T16: =IF(Q16="","",P16/Q16)
A17: 7 | E17: 2 | F17: =(Componentes!AB12/(Componentes!AB12+Componentes!AB15))*Componentes!P12+(Componentes!AB15/(Componentes!AB12+Componentes!AB15))*Componentes!P15 -> 0.90566129 | G17: =IF(#REF!="","",#REF!*7/$B$5) -> #REF! | H17: =IF(#REF!="","",#REF!*7/$B$4) -> #REF! | I17: =IF(#REF!="","",#REF!*7/F17) -> #REF! | N17: =IF(OR(J17="",K17=""),"",K17-J17) | O17: =IF(OR(K17="",L17=""),"",L17-K17) | P17: =IF(OR(L17="",M17=""),"",M17-L17) | Q17: =IF(OR(J17="",M17=""),"",M17-J17) | R17: =IF(Q17="","",N17/Q17) | S17: =IF(Q17="","",O17/Q17) | T17: =IF(Q17="","",P17/Q17)
A18: 8 | E18: 3 | F18: =(Componentes!AB12/(Componentes!AB12+Componentes!AB15))*Componentes!P12+(Componentes!AB15/(Componentes!AB12+Componentes!AB15))*Componentes!P15 -> 0.90566129 | G18: =IF(#REF!="","",#REF!*7/$B$5) -> #REF! | H18: =IF(#REF!="","",#REF!*7/$B$4) -> #REF! | I18: =IF(#REF!="","",#REF!*7/F18) -> #REF! | N18: =IF(OR(J18="",K18=""),"",K18-J18) | O18: =IF(OR(K18="",L18=""),"",L18-K18) | P18: =IF(OR(L18="",M18=""),"",M18-L18) | Q18: =IF(OR(J18="",M18=""),"",M18-J18) | R18: =IF(Q18="","",N18/Q18) | S18: =IF(Q18="","",O18/Q18) | T18: =IF(Q18="","",P18/Q18)
A19: 9 | E19: 4 | F19: =(Componentes!AB12/(Componentes!AB12+Componentes!AB15))*Componentes!P12+(Componentes!AB15/(Componentes!AB12+Componentes!AB15))*Componentes!P15 -> 0.90566129 | G19: =IF(#REF!="","",#REF!*7/$B$5) -> #REF! | H19: =IF(#REF!="","",#REF!*7/$B$4) -> #REF! | I19: =IF(#REF!="","",#REF!*7/F19) -> #REF! | N19: =IF(OR(J19="",K19=""),"",K19-J19) | O19: =IF(OR(K19="",L19=""),"",L19-K19) | P19: =IF(OR(L19="",M19=""),"",M19-L19) | Q19: =IF(OR(J19="",M19=""),"",M19-J19) | R19: =IF(Q19="","",N19/Q19) | S19: =IF(Q19="","",O19/Q19) | T19: =IF(Q19="","",P19/Q19)
A20: 10 | E20: 5 | F20: =(Componentes!AB12/(Componentes!AB12+Componentes!AB15))*Componentes!P12+(Componentes!AB15/(Componentes!AB12+Componentes!AB15))*Componentes!P15 -> 0.90566129 | G20: =IF(#REF!="","",#REF!*7/$B$5) -> #REF! | H20: =IF(#REF!="","",#REF!*7/$B$4) -> #REF! | I20: =IF(#REF!="","",#REF!*7/F20) -> #REF! | N20: =IF(OR(J20="",K20=""),"",K20-J20) | O20: =IF(OR(K20="",L20=""),"",L20-K20) | P20: =IF(OR(L20="",M20=""),"",M20-L20) | Q20: =IF(OR(J20="",M20=""),"",M20-J20) | R20: =IF(Q20="","",N20/Q20) | S20: =IF(Q20="","",O20/Q20) | T20: =IF(Q20="","",P20/Q20)
A22: 11 | B22: ThyCarvac | C22: Thymol | D22: Carvacrol | E22: 1 | F22: =(Componentes!AB12/(Componentes!AB12+Componentes!AB16))*Componentes!P12+(Componentes!AB16/(Componentes!AB12+Componentes!AB16))*Componentes!P16 -> 0.85403 | G22: =IF(#REF!="","",#REF!*7/$B$5) -> #REF! | H22: =IF(#REF!="","",#REF!*7/$B$4) -> #REF! | I22: =IF(#REF!="","",#REF!*7/F22) -> #REF! | N22: =IF(OR(J22="",K22=""),"",K22-J22) | O22: =IF(OR(K22="",L22=""),"",L22-K22) | P22: =IF(OR(L22="",M22=""),"",M22-L22) | Q22: =IF(OR(J22="",M22=""),"",M22-J22) | R22: =IF(Q22="","",N22/Q22) | S22: =IF(Q22="","",O22/Q22) | T22: =IF(Q22="","",P22/Q22)
A23: 12 | E23: 2 | F23: =(Componentes!AB12/(Componentes!AB12+Componentes!AB16))*Componentes!P12+(Componentes!AB16/(Componentes!AB12+Componentes!AB16))*Componentes!P16 -> 0.85403 | G23: =IF(#REF!="","",#REF!*7/$B$5) -> #REF! | H23: =IF(#REF!="","",#REF!*7/$B$4) -> #REF! | I23: =IF(#REF!="","",#REF!*7/F23) -> #REF! | N23: =IF(OR(J23="",K23=""),"",K23-J23) | O23: =IF(OR(K23="",L23=""),"",L23-K23) | P23: =IF(OR(L23="",M23=""),"",M23-L23) | Q23: =IF(OR(J23="",M23=""),"",M23-J23) | R23: =IF(Q23="","",N23/Q23) | S23: =IF(Q23="","",O23/Q23) | T23: =IF(Q23="","",P23/Q23)
A24: 13 | E24: 3 | F24: =(Componentes!AB12/(Componentes!AB12+Componentes!AB16))*Componentes!P12+(Componentes!AB16/(Componentes!AB12+Componentes!AB16))*Componentes!P16 -> 0.85403 | G24: =IF(#REF!="","",#REF!*7/$B$5) -> #REF! | H24: =IF(#REF!="","",#REF!*7/$B$4) -> #REF! | I24: =IF(#REF!="","",#REF!*7/F24) -> #REF! | N24: =IF(OR(J24="",K24=""),"",K24-J24) | O24: =IF(OR(K24="",L24=""),"",L24-K24) | P24: =IF(OR(L24="",M24=""),"",M24-L24) | Q24: =IF(OR(J24="",M24=""),"",M24-J24) | R24: =IF(Q24="","",N24/Q24) | S24: =IF(Q24="","",O24/Q24) | T24: =IF(Q24="","",P24/Q24)
A25: 14 | E25: 4 | F25: =(Componentes!AB12/(Componentes!AB12+Componentes!AB16))*Componentes!P12+(Componentes!AB16/(Componentes!AB12+Componentes!AB16))*Componentes!P16 -> 0.85403 | G25: =IF(#REF!="","",#REF!*7/$B$5) -> #REF! | H25: =IF(#REF!="","",#REF!*7/$B$4) -> #REF! | I25: =IF(#REF!="","",#REF!*7/F25) -> #REF! | N25: =IF(OR(J25="",K25=""),"",K25-J25) | O25: =IF(OR(K25="",L25=""),"",L25-K25) | P25: =IF(OR(L25="",M25=""),"",M25-L25) | Q25: =IF(OR(J25="",M25=""),"",M25-J25) | R25: =IF(Q25="","",N25/Q25) | S25: =IF(Q25="","",O25/Q25) | T25: =IF(Q25="","",P25/Q25)
A26: 15 | E26: 5 | F26: =(Componentes!AB12/(Componentes!AB12+Componentes!AB16))*Componentes!P12+(Componentes!AB16/(Componentes!AB12+Componentes!AB16))*Componentes!P16 -> 0.85403 | G26: =IF(#REF!="","",#REF!*7/$B$5) -> #REF! | H26: =IF(#REF!="","",#REF!*7/$B$4) -> #REF! | I26: =IF(#REF!="","",#REF!*7/F26) -> #REF! | N26: =IF(OR(J26="",K26=""),"",K26-J26) | O26: =IF(OR(K26="",L26=""),"",L26-K26) | P26: =IF(OR(L26="",M26=""),"",M26-L26) | Q26: =IF(OR(J26="",M26=""),"",M26-J26) | R26: =IF(Q26="","",N26/Q26) | S26: =IF(Q26="","",O26/Q26) | T26: =IF(Q26="","",P26/Q26)
A28: 16 | B28: ThyEug | C28: Thymol | D28: Eugenol | E28: 1 | F28: =(Componentes!AB12/(Componentes!AB12+Componentes!AB17))*Componentes!P12+(Componentes!AB17/(Componentes!AB12+Componentes!AB17))*Componentes!P17 -> 0.90154123 | G28: =IF(#REF!="","",#REF!*7/$B$5) -> #REF! | H28: =IF(#REF!="","",#REF!*7/$B$4) -> #REF! | I28: =IF(#REF!="","",#REF!*7/F28) -> #REF! | N28: =IF(OR(J28="",K28=""),"",K28-J28) | O28: =IF(OR(K28="",L28=""),"",L28-K28) | P28: =IF(OR(L28="",M28=""),"",M28-L28) | Q28: =IF(OR(J28="",M28=""),"",M28-J28) | R28: =IF(Q28="","",N28/Q28) | S28: =IF(Q28="","",O28/Q28) | T28: =IF(Q28="","",P28/Q28)
A29: 17 | E29: 2 | F29: =(Componentes!AB12/(Componentes!AB12+Componentes!AB17))*Componentes!P12+(Componentes!AB17/(Componentes!AB12+Componentes!AB17))*Componentes!P17 -> 0.90154123 | G29: =IF(#REF!="","",#REF!*7/$B$5) -> #REF! | H29: =IF(#REF!="","",#REF!*7/$B$4) -> #REF! | I29: =IF(#REF!="","",#REF!*7/F29) -> #REF! | N29: =IF(OR(J29="",K29=""),"",K29-J29) | O29: =IF(OR(K29="",L29=""),"",L29-K29) | P29: =IF(OR(L29="",M29=""),"",M29-L29) | Q29: =IF(OR(J29="",M29=""),"",M29-J29) | R29: =IF(Q29="","",N29/Q29) | S29: =IF(Q29="","",O29/Q29) | T29: =IF(Q29="","",P29/Q29)
A30: 18 | E30: 3 | F30: =(Componentes!AB12/(Componentes!AB12+Componentes!AB17))*Componentes!P12+(Componentes!AB17/(Componentes!AB12+Componentes!AB17))*Componentes!P17 -> 0.90154123 | G30: =IF(#REF!="","",#REF!*7/$B$5) -> #REF! | H30: =IF(#REF!="","",#REF!*7/$B$4) -> #REF! | I30: =IF(#REF!="","",#REF!*7/F30) -> #REF! | N30: =IF(OR(J30="",K30=""),"",K30-J30) | O30: =IF(OR(K30="",L30=""),"",L30-K30) | P30: =IF(OR(L30="",M30=""),"",M30-L30) | Q30: =IF(OR(J30="",M30=""),"",M30-J30) | R30: =IF(Q30="","",N30/Q30) | S30: =IF(Q30="","",O30/Q30) | T30: =IF(Q30="","",P30/Q30)
A31: 19 | E31: 4 | F31: =(Componentes!AB12/(Componentes!AB12+Componentes!AB17))*Componentes!P12+(Componentes!AB17/(Componentes!AB12+Componentes!AB17))*Componentes!P17 -> 0.90154123 | G31: =IF(#REF!="","",#REF!*7/$B$5) -> #REF! | H31: =IF(#REF!="","",#REF!*7/$B$4) -> #REF! | I31: =IF(#REF!="","",#REF!*7/F31) -> #REF! | N31: =IF(OR(J31="",K31=""),"",K31-J31) | O31: =IF(OR(K31="",L31=""),"",L31-K31) | P31: =IF(OR(L31="",M31=""),"",M31-L31) | Q31: =IF(OR(J31="",M31=""),"",M31-J31) | R31: =IF(Q31="","",N31/Q31) | S31: =IF(Q31="","",O31/Q31) | T31: =IF(Q31="","",P31/Q31)
A32: 20 | E32: 5 | F32: =(Componentes!AB12/(Componentes!AB12+Componentes!AB17))*Componentes!P12+(Componentes!AB17/(Componentes!AB12+Componentes!AB17))*Componentes!P17 -> 0.90154123 | G32: =IF(#REF!="","",#REF!*7/$B$5) -> #REF! | H32: =IF(#REF!="","",#REF!*7/$B$4) -> #REF! | I32: =IF(#REF!="","",#REF!*7/F32) -> #REF! | N32: =IF(OR(J32="",K32=""),"",K32-J32) | O32: =IF(OR(K32="",L32=""),"",L32-K32) | P32: =IF(OR(L32="",M32=""),"",M32-L32) | Q32: =IF(OR(J32="",M32=""),"",M32-J32) | R32: =IF(Q32="","",N32/Q32) | S32: =IF(Q32="","",O32/Q32) | T32: =IF(Q32="","",P32/Q32)
A34: 21 | B34: ThyCam | C34: Thymol | D34: Camphor | E34: 1 | F34: =(Componentes!AB12/(Componentes!AB12+Componentes!AB14))*Componentes!P12+(Componentes!AB14/(Componentes!AB12+Componentes!AB14))*Componentes!P14 -> 0.89000064 | G34: =IF(#REF!="","",#REF!*7/$B$5) -> #REF! | H34: =IF(#REF!="","",#REF!*7/$B$4) -> #REF! | I34: =IF(#REF!="","",#REF!*7/F34) -> #REF! | N34: =IF(OR(J34="",K34=""),"",K34-J34) | O34: =IF(OR(K34="",L34=""),"",L34-K34) | P34: =IF(OR(L34="",M34=""),"",M34-L34) | Q34: =IF(OR(J34="",M34=""),"",M34-J34) | R34: =IF(Q34="","",N34/Q34) | S34: =IF(Q34="","",O34/Q34) | T34: =IF(Q34="","",P34/Q34)
A35: 22 | E35: 2 | F35: =(Componentes!AB12/(Componentes!AB12+Componentes!AB14))*Componentes!P12+(Componentes!AB14/(Componentes!AB12+Componentes!AB14))*Componentes!P14 -> 0.89000064 | G35: =IF(#REF!="","",#REF!*7/$B$5) -> #REF! | H35: =IF(#REF!="","",#REF!*7/$B$4) -> #REF! | I35: =IF(#REF!="","",#REF!*7/F35) -> #REF! | N35: =IF(OR(J35="",K35=""),"",K35-J35) | O35: =IF(OR(K35="",L35=""),"",L35-K35) | P35: =IF(OR(L35="",M35=""),"",M35-L35) | Q35: =IF(OR(J35="",M35=""),"",M35-J35) | R35: =IF(Q35="","",N35/Q35) | S35: =IF(Q35="","",O35/Q35) | T35: =IF(Q35="","",P35/Q35)
A36: 23 | E36: 3 | F36: =(Componentes!AB12/(Componentes!AB12+Componentes!AB14))*Componentes!P12+(Componentes!AB14/(Componentes!AB12+Componentes!AB14))*Componentes!P14 -> 0.89000064 | G36: =IF(#REF!="","",#REF!*7/$B$5) -> #REF! | H36: =IF(#REF!="","",#REF!*7/$B$4) -> #REF! | I36: =IF(#REF!="","",#REF!*7/F36) -> #REF! | N36: =IF(OR(J36="",K36=""),"",K36-J36) | O36: =IF(OR(K36="",L36=""),"",L36-K36) | P36: =IF(OR(L36="",M36=""),"",M36-L36) | Q36: =IF(OR(J36="",M36=""),"",M36-J36) | R36: =IF(Q36="","",N36/Q36) | S36: =IF(Q36="","",O36/Q36) | T36: =IF(Q36="","",P36/Q36)
A37: 24 | E37: 4 | F37: =(Componentes!AB12/(Componentes!AB12+Componentes!AB14))*Componentes!P12+(Componentes!AB14/(Componentes!AB12+Componentes!AB14))*Componentes!P14 -> 0.89000064 | G37: =IF(#REF!="","",#REF!*7/$B$5) -> #REF! | H37: =IF(#REF!="","",#REF!*7/$B$4) -> #REF! | I37: =IF(#REF!="","",#REF!*7/F37) -> #REF! | N37: =IF(OR(J37="",K37=""),"",K37-J37) | O37: =IF(OR(K37="",L37=""),"",L37-K37) | P37: =IF(OR(L37="",M37=""),"",M37-L37) | Q37: =IF(OR(J37="",M37=""),"",M37-J37) | R37: =IF(Q37="","",N37/Q37) | S37: =IF(Q37="","",O37/Q37) | T37: =IF(Q37="","",P37/Q37)
A38: 25 | E38: 5 | F38: =(Componentes!AB12/(Componentes!AB12+Componentes!AB14))*Componentes!P12+(Componentes!AB14/(Componentes!AB12+Componentes!AB14))*Componentes!P14 -> 0.89000064 | G38: =IF(#REF!="","",#REF!*7/$B$5) -> #REF! | H38: =IF(#REF!="","",#REF!*7/$B$4) -> #REF! | I38: =IF(#REF!="","",#REF!*7/F38) -> #REF! | N38: =IF(OR(J38="",K38=""),"",K38-J38) | O38: =IF(OR(K38="",L38=""),"",L38-K38) | P38: =IF(OR(L38="",M38=""),"",M38-L38) | Q38: =IF(OR(J38="",M38=""),"",M38-J38) | R38: =IF(Q38="","",N38/Q38) | S38: =IF(Q38="","",O38/Q38) | T38: =IF(Q38="","",P38/Q38)
A40: 26 | B40: CamCar | C40: Camphor | D40: Carvone | E40: 1 | F40: =(Componentes!AB14/(Componentes!AB14+Componentes!AB13))*Componentes!P14+(Componentes!AB13/(Componentes!AB14+Componentes!AB13))*Componentes!P13 -> 0.96 | G40: =IF(#REF!="","",#REF!*7/$B$5) -> #REF! | H40: =IF(#REF!="","",#REF!*7/$B$4) -> #REF! | I40: =IF(#REF!="","",#REF!*7/F40) -> #REF! | N40: =IF(OR(J40="",K40=""),"",K40-J40) | O40: =IF(OR(K40="",L40=""),"",L40-K40) | P40: =IF(OR(L40="",M40=""),"",M40-L40) | Q40: =IF(OR(J40="",M40=""),"",M40-J40) | R40: =IF(Q40="","",N40/Q40) | S40: =IF(Q40="","",O40/Q40) | T40: =IF(Q40="","",P40/Q40)
A41: 27 | E41: 2 | F41: =(Componentes!AB14/(Componentes!AB14+Componentes!AB13))*Componentes!P14+(Componentes!AB13/(Componentes!AB14+Componentes!AB13))*Componentes!P13 -> 0.96 | G41: =IF(#REF!="","",#REF!*7/$B$5) -> #REF! | H41: =IF(#REF!="","",#REF!*7/$B$4) -> #REF! | I41: =IF(#REF!="","",#REF!*7/F41) -> #REF! | N41: =IF(OR(J41="",K41=""),"",K41-J41) | O41: =IF(OR(K41="",L41=""),"",L41-K41) | P41: =IF(OR(L41="",M41=""),"",M41-L41) | Q41: =IF(OR(J41="",M41=""),"",M41-J41) | R41: =IF(Q41="","",N41/Q41) | S41: =IF(Q41="","",O41/Q41) | T41: =IF(Q41="","",P41/Q41)
A42: 28 | E42: 3 | F42: =(Componentes!AB14/(Componentes!AB14+Componentes!AB13))*Componentes!P14+(Componentes!AB13/(Componentes!AB14+Componentes!AB13))*Componentes!P13 -> 0.96 | G42: =IF(#REF!="","",#REF!*7/$B$5) -> #REF! | H42: =IF(#REF!="","",#REF!*7/$B$4) -> #REF! | I42: =IF(#REF!="","",#REF!*7/F42) -> #REF! | N42: =IF(OR(J42="",K42=""),"",K42-J42) | O42: =IF(OR(K42="",L42=""),"",L42-K42) | P42: =IF(OR(L42="",M42=""),"",M42-L42) | Q42: =IF(OR(J42="",M42=""),"",M42-J42) | R42: =IF(Q42="","",N42/Q42) | S42: =IF(Q42="","",O42/Q42) | T42: =IF(Q42="","",P42/Q42)
A43: 29 | E43: 4 | F43: =(Componentes!AB14/(Componentes!AB14+Componentes!AB13))*Componentes!P14+(Componentes!AB13/(Componentes!AB14+Componentes!AB13))*Componentes!P13 -> 0.96 | G43: =IF(#REF!="","",#REF!*7/$B$5) -> #REF! | H43: =IF(#REF!="","",#REF!*7/$B$4) -> #REF! | I43: =IF(#REF!="","",#REF!*7/F43) -> #REF! | N43: =IF(OR(J43="",K43=""),"",K43-J43) | O43: =IF(OR(K43="",L43=""),"",L43-K43) | P43: =IF(OR(L43="",M43=""),"",M43-L43) | Q43: =IF(OR(J43="",M43=""),"",M43-J43) | R43: =IF(Q43="","",N43/Q43) | S43: =IF(Q43="","",O43/Q43) | T43: =IF(Q43="","",P43/Q43)
A44: 30 | E44: 5 | F44: =(Componentes!AB14/(Componentes!AB14+Componentes!AB13))*Componentes!P14+(Componentes!AB13/(Componentes!AB14+Componentes!AB13))*Componentes!P13 -> 0.96 | G44: =IF(#REF!="","",#REF!*7/$B$5) -> #REF! | H44: =IF(#REF!="","",#REF!*7/$B$4) -> #REF! | I44: =IF(#REF!="","",#REF!*7/F44) -> #REF! | N44: =IF(OR(J44="",K44=""),"",K44-J44) | O44: =IF(OR(K44="",L44=""),"",L44-K44) | P44: =IF(OR(L44="",M44=""),"",M44-L44) | Q44: =IF(OR(J44="",M44=""),"",M44-J44) | R44: =IF(Q44="","",N44/Q44) | S44: =IF(Q44="","",O44/Q44) | T44: =IF(Q44="","",P44/Q44)
A46: 31 | B46: CamGer | C46: Camphor | D46: Geraniol | E46: 1 | F46: =(Componentes!AB14/(Componentes!AB14+Componentes!AB15))*Componentes!P14+(Componentes!AB15/(Componentes!AB14+Componentes!AB15))*Componentes!P15 -> 0.97509837 | G46: =IF(#REF!="","",#REF!*7/$B$5) -> #REF! | H46: =IF(#REF!="","",#REF!*7/$B$4) -> #REF! | I46: =IF(#REF!="","",#REF!*7/F46) -> #REF! | N46: =IF(OR(J46="",K46=""),"",K46-J46) | O46: =IF(OR(K46="",L46=""),"",L46-K46) | P46: =IF(OR(L46="",M46=""),"",M46-L46) | Q46: =IF(OR(J46="",M46=""),"",M46-J46) | R46: =IF(Q46="","",N46/Q46) | S46: =IF(Q46="","",O46/Q46) | T46: =IF(Q46="","",P46/Q46)
A47: 32 | E47: 2 | F47: =(Componentes!AB14/(Componentes!AB14+Componentes!AB15))*Componentes!P14+(Componentes!AB15/(Componentes!AB14+Componentes!AB15))*Componentes!P15 -> 0.97509837 | G47: =IF(#REF!="","",#REF!*7/$B$5) -> #REF! | H47: =IF(#REF!="","",#REF!*7/$B$4) -> #REF! | I47: =IF(#REF!="","",#REF!*7/F47) -> #REF! | N47: =IF(OR(J47="",K47=""),"",K47-J47) | O47: =IF(OR(K47="",L47=""),"",L47-K47) | P47: =IF(OR(L47="",M47=""),"",M47-L47) | Q47: =IF(OR(J47="",M47=""),"",M47-J47) | R47: =IF(Q47="","",N47/Q47) | S47: =IF(Q47="","",O47/Q47) | T47: =IF(Q47="","",P47/Q47)
A48: 33 | E48: 3 | F48: =(Componentes!AB14/(Componentes!AB14+Componentes!AB15))*Componentes!P14+(Componentes!AB15/(Componentes!AB14+Componentes!AB15))*Componentes!P15 -> 0.97509837 | G48: =IF(#REF!="","",#REF!*7/$B$5) -> #REF! | H48: =IF(#REF!="","",#REF!*7/$B$4) -> #REF! | I48: =IF(#REF!="","",#REF!*7/F48) -> #REF! | N48: =IF(OR(J48="",K48=""),"",K48-J48) | O48: =IF(OR(K48="",L48=""),"",L48-K48) | P48: =IF(OR(L48="",M48=""),"",M48-L48) | Q48: =IF(OR(J48="",M48=""),"",M48-J48) | R48: =IF(Q48="","",N48/Q48) | S48: =IF(Q48="","",O48/Q48) | T48: =IF(Q48="","",P48/Q48)
A49: 34 | E49: 4 | F49: =(Componentes!AB14/(Componentes!AB14+Componentes!AB15))*Componentes!P14+(Componentes!AB15/(Componentes!AB14+Componentes!AB15))*Componentes!P15 -> 0.97509837 | G49: =IF(#REF!="","",#REF!*7/$B$5) -> #REF! | H49: =IF(#REF!="","",#REF!*7/$B$4) -> #REF! | I49: =IF(#REF!="","",#REF!*7/F49) -> #REF! | N49: =IF(OR(J49="",K49=""),"",K49-J49) | O49: =IF(OR(K49="",L49=""),"",L49-K49) | P49: =IF(OR(L49="",M49=""),"",M49-L49) | Q49: =IF(OR(J49="",M49=""),"",M49-J49) | R49: =IF(Q49="","",N49/Q49) | S49: =IF(Q49="","",O49/Q49) | T49: =IF(Q49="","",P49/Q49)
...

Sheet Sampling
A1: A — ThyCar (Thymol + Carvone) | H1: V_sample: | I1: 200 | J1: µL | K1: +800 µL IPA
A2: 2-phenylethanol + DES + Water | DF=5 | Split 20:1 | 1.0 µL | DB-WAX | I2: ■ KF routine | J2: □ KF if fishy
A3: System | B3: Phase | C3: Rep | D3: GC Vial ID | E3: W_vial (g) | F3: W +sample (g) | G3: W +solvent (g) | H3: m_sample (g) | I3: m_solvent (g) | J3: DF | K3: KF w_water (%) | L3: Notes
A4: A1 | B4: Top | C4: 1 | D4: A1-T1 | H4: =IF(OR(E4="",F4=""),"",F4-E4) | I4: =IF(OR(F4="",G4=""),"",G4-F4) | J4: =IF(OR(H4="",I4=""),"",(H4+I4)/H4)
C5: 2 | D5: A1-T2 | H5: =IF(OR(E5="",F5=""),"",F5-E5) | I5: =IF(OR(F5="",G5=""),"",G5-F5) | J5: =IF(OR(H5="",I5=""),"",(H5+I5)/H5)
B6: Bot | C6: 1 | D6: A1-B1 | H6: =IF(OR(E6="",F6=""),"",F6-E6) | I6: =IF(OR(F6="",G6=""),"",G6-F6) | J6: =IF(OR(H6="",I6=""),"",(H6+I6)/H6)
C7: 2 | D7: A1-B2 | H7: =IF(OR(E7="",F7=""),"",F7-E7) | I7: =IF(OR(F7="",G7=""),"",G7-F7) | J7: =IF(OR(H7="",I7=""),"",(H7+I7)/H7)
A8: A2 | B8: Top | C8: 1 | D8: A2-T1 | H8: =IF(OR(E8="",F8=""),"",F8-E8) | I8: =IF(OR(F8="",G8=""),"",G8-F8) | J8: =IF(OR(H8="",I8=""),"",(H8+I8)/H8)
C9: 2 | D9: A2-T2 | H9: =IF(OR(E9="",F9=""),"",F9-E9) | I9: =IF(OR(F9="",G9=""),"",G9-F9) | J9: =IF(OR(H9="",I9=""),"",(H9+I9)/H9)
B10: Bot | C10: 1 | D10: A2-B1 | H10: =IF(OR(E10="",F10=""),"",F10-E10) | I10: =IF(OR(F10="",G10=""),"",G10-F10) | J10: =IF(OR(H10="",I10=""),"",(H10+I10)/H10)
C11: 2 | D11: A2-B2 | H11: =IF(OR(E11="",F11=""),"",F11-E11) | I11: =IF(OR(F11="",G11=""),"",G11-F11) | J11: =IF(OR(H11="",I11=""),"",(H11+I11)/H11)
A12: A3 | B12: Top | C12: 1 | D12: A3-T1 | H12: =IF(OR(E12="",F12=""),"",F12-E12) | I12: =IF(OR(F12="",G12=""),"",G12-F12) | J12: =IF(OR(H12="",I12=""),"",(H12+I12)/H12)
C13: 2 | D13: A3-T2 | H13: =IF(OR(E13="",F13=""),"",F13-E13) | I13: =IF(OR(F13="",G13=""),"",G13-F13) | J13: =IF(OR(H13="",I13=""),"",(H13+I13)/H13)
B14: Bot | C14: 1 | D14: A3-B1 | H14: =IF(OR(E14="",F14=""),"",F14-E14) | I14: =IF(OR(F14="",G14=""),"",G14-F14) | J14: =IF(OR(H14="",I14=""),"",(H14+I14)/H14)
C15: 2 | D15: A3-B2 | H15: =IF(OR(E15="",F15=""),"",F15-E15) | I15: =IF(OR(F15="",G15=""),"",G15-F15) | J15: =IF(OR(H15="",I15=""),"",(H15+I15)/H15)
A16: A4 | B16: Top | C16: 1 | D16: A4-T1 | H16: =IF(OR(E16="",F16=""),"",F16-E16) | I16: =IF(OR(F16="",G16=""),"",G16-F16) | J16: =IF(OR(H16="",I16=""),"",(H16+I16)/H16)
C17: 2 | D17: A4-T2 | H17: =IF(OR(E17="",F17=""),"",F17-E17) | I17: =IF(OR(F17="",G17=""),"",G17-F17) | J17: =IF(OR(H17="",I17=""),"",(H17+I17)/H17)
B18: Bot | C18: 1 | D18: A4-B1 | H18: =IF(OR(E18="",F18=""),"",F18-E18) | I18: =IF(OR(F18="",G18=""),"",G18-F18) | J18: =IF(OR(H18="",I18=""),"",(H18+I18)/H18)
C19: 2 | D19: A4-B2 | H19: =IF(OR(E19="",F19=""),"",F19-E19) | I19: =IF(OR(F19="",G19=""),"",G19-F19) | J19: =IF(OR(H19="",I19=""),"",(H19+I19)/H19)
A20: A5 | B20: Top | C20: 1 | D20: A5-T1 | H20: =IF(OR(E20="",F20=""),"",F20-E20) | I20: =IF(OR(F20="",G20=""),"",G20-F20) | J20: =IF(OR(H20="",I20=""),"",(H20+I20)/H20)
C21: 2 | D21: A5-T2 | H21: =IF(OR(E21="",F21=""),"",F21-E21) | I21: =IF(OR(F21="",G21=""),"",G21-F21) | J21: =IF(OR(H21="",I21=""),"",(H21+I21)/H21)
B22: Bot | C22: 1 | D22: A5-B1 | H22: =IF(OR(E22="",F22=""),"",F22-E22) | I22: =IF(OR(F22="",G22=""),"",G22-F22) | J22: =IF(OR(H22="",I22=""),"",(H22+I22)/H22)
C23: 2 | D23: A5-B2 | H23: =IF(OR(E23="",F23=""),"",F23-E23) | I23: =IF(OR(F23="",G23=""),"",G23-F23) | J23: =IF(OR(H23="",I23=""),"",(H23+I23)/H23)
A24: B — ThyGer (Thymol + Geraniol) | H24: V_sample: | I24: 200 | J24: µL | K24: +800 µL IPA
A25: 2-phenylethanol + DES + Water | DF=5 | Split 20:1 | 1.0 µL | DB-WAX | I25: ■ KF routine | J25: □ KF if fishy
A26: System | B26: Phase | C26: Rep | D26: GC Vial ID | E26: W_vial (g) | F26: W +sample (g) | G26: W +solvent (g) | H26: m_sample (g) | I26: m_solvent (g) | J26: DF | K26: KF w_water (%) | L26: Notes
A27: B1 | B27: Top | C27: 1 | D27: B1-T1 | H27: =IF(OR(E27="",F27=""),"",F27-E27) | I27: =IF(OR(F27="",G27=""),"",G27-F27) | J27: =IF(OR(H27="",I27=""),"",(H27+I27)/H27)
C28: 2 | D28: B1-T2 | H28: =IF(OR(E28="",F28=""),"",F28-E28) | I28: =IF(OR(F28="",G28=""),"",G28-F28) | J28: =IF(OR(H28="",I28=""),"",(H28+I28)/H28)
B29: Bot | C29: 1 | D29: B1-B1 | H29: =IF(OR(E29="",F29=""),"",F29-E29) | I29: =IF(OR(F29="",G29=""),"",G29-F29) | J29: =IF(OR(H29="",I29=""),"",(H29+I29)/H29)
C30: 2 | D30: B1-B2 | H30: =IF(OR(E30="",F30=""),"",F30-E30) | I30: =IF(OR(F30="",G30=""),"",G30-F30) | J30: =IF(OR(H30="",I30=""),"",(H30+I30)/H30)
A31: B2 | B31: Top | C31: 1 | D31: B2-T1 | H31: =IF(OR(E31="",F31=""),"",F31-E31) | I31: =IF(OR(F31="",G31=""),"",G31-F31) | J31: =IF(OR(H31="",I31=""),"",(H31+I31)/H31)
C32: 2 | D32: B2-T2 | H32: =IF(OR(E32="",F32=""),"",F32-E32) | I32: =IF(OR(F32="",G32=""),"",G32-F32) | J32: =IF(OR(H32="",I32=""),"",(H32+I32)/H32)
B33: Bot | C33: 1 | D33: B2-B1 | H33: =IF(OR(E33="",F33=""),"",F33-E33) | I33: =IF(OR(F33="",G33=""),"",G33-F33) | J33: =IF(OR(H33="",I33=""),"",(H33+I33)/H33)
C34: 2 | D34: B2-B2 | H34: =IF(OR(E34="",F34=""),"",F34-E34) | I34: =IF(OR(F34="",G34=""),"",G34-F34) | J34: =IF(OR(H34="",I34=""),"",(H34+I34)/H34)
A35: B3 | B35: Top | C35: 1 | D35: B3-T1 | H35: =IF(OR(E35="",F35=""),"",F35-E35) | I35: =IF(OR(F35="",G35=""),"",G35-F35) | J35: =IF(OR(H35="",I35=""),"",(H35+I35)/H35)
C36: 2 | D36: B3-T2 | H36: =IF(OR(E36="",F36=""),"",F36-E36) | I36: =IF(OR(F36="",G36=""),"",G36-F36) | J36: =IF(OR(H36="",I36=""),"",(H36+I36)/H36)
B37: Bot | C37: 1 | D37: B3-B1 | H37: =IF(OR(E37="",F37=""),"",F37-E37) | I37: =IF(OR(F37="",G37=""),"",G37-F37) | J37: =IF(OR(H37="",I37=""),"",(H37+I37)/H37)
C38: 2 | D38: B3-B2 | H38: =IF(OR(E38="",F38=""),"",F38-E38) | I38: =IF(OR(F38="",G38=""),"",G38-F38) | J38: =IF(OR(H38="",I38=""),"",(H38+I38)/H38)
A39: B4 | B39: Top | C39: 1 | D39: B4-T1 | H39: =IF(OR(E39="",F39=""),"",F39-E39) | I39: =IF(OR(F39="",G39=""),"",G39-F39) | J39: =IF(OR(H39="",I39=""),"",(H39+I39)/H39)
C40: 2 | D40: B4-T2 | H40: =IF(OR(E40="",F40=""),"",F40-E40) | I40: =IF(OR(F40="",G40=""),"",G40-F40) | J40: =IF(OR(H40="",I40=""),"",(H40+I40)/H40)
...
